Workbook

Sheet ENERO
B3: ALIMENTO | C3: 45659 | D3: 45660 | E3: 45661 | F3: SUB TOTAL | G3: MONTO | H3: 45663 | I3: 45664 | J3: 45665 | K3: 45666 | L3: 45667 | M3: 45668 | N3: SUB TOTAL | O3: MONTO | P3: 45670 | Q3: 45671 | R3: 45672 | S3: 45673 | T3: 45674 | U3: 45675 | V3: SUB TOTAL | W3: MONTO | X3: 45677 | Y3: 45678 | Z3: 45679 | AA3: 45680 | AB3: 45681 | AC3: 45682 | AD3: SUB TOTAL | AE3: MONTO | AF3: 45684 | AG3: 45685 | AH3: 45686 | AI3: 45687 | AJ3: 45688 | AK3: SUB TOTAL | AL3: MONTO | AS3: MES : ENERO
B4: ENG CARNE | C4: 20 | D4: 50 | E4: 20 | F4: =SUM(C4:E4) -> 90 | G4: =F4*60 -> 5400 | H4: 28 | I4: 22 | J4: 26 | K4: 48 | L4: 35 | M4: 41 | N4: =SUM(H4:M4) -> 200 | O4: =N4*60 -> 12000 | P4: 5 | Q4: 58 | R4: - | S4: 13 | T4: 7 | U4: 10 | V4: =SUM(P4:U4) -> 93 | W4: =V4*60 -> 5580 | X4: 20 | Y4: 91 | Z4: 16 | AA4: 46 | AB4: 43 | AC4: - | AD4: =SUM(X4:AC4) -> 216 | AE4: =AD4*60 -> 12960 | AF4: 54 | AG4: 115 | AH4: 57 | AI4: 20 | AJ4: 20 | AK4: =SUM(AF4:AJ4) -> 266 | AL4: =AK4*60 -> 15960 | AS4: ALIMENTOS | AT4: =AO19 -> 5992
B5: CTO CARNE | C5: 10 | D5: 67 | E5: 5 | F5: =SUM(C5:E5) -> 82 | G5: =F5*60 -> 4920 | H5: 5 | I5: 17 | J5: 19 | K5: 31 | L5: 43 | M5: 54 | N5: =SUM(H5:M5) -> 169 | O5: =N5*60 -> 10140 | P5: 13 | Q5: 44 | R5: 10 | S5: 38 | T5: 7 | U5: 10 | V5: =SUM(P5:U5) -> 122 | W5: =V5*60 -> 7320 | X5: 10 | Y5: 69 | Z5: 15 | AA5: 45 | AB5: 17 | AC5: - | AD5: =SUM(X5:AC5) -> 156 | AE5: =AD5*60 -> 9360 | AF5: 34 | AG5: 52 | AH5: 52 | AI5: 25 | AJ5: 10 | AK5: =SUM(AF5:AJ5) -> 173 | AL5: =AK5*60 -> 10380 | AS5: VALOR M. | AT5: =AO20 -> 439146
B6: INICIO CARNE | C6: - | D6: 17 | E6: 5 | F6: =SUM(C6:E6) -> 22 | G6: =F6*61 -> 1342 | H6: 6 | I6: 28 | J6: 2 | K6: 18 | L6: 7 | M6: 8 | N6: =SUM(H6:M6) -> 69 | O6: =N6*61 -> 4209 | P6: 11 | Q6: 6 | S6: - | T6: - | U6: 40 | V6: =SUM(P6:U6) -> 57 | W6: =V6*61 -> 3477 | X6: 16 | Y6: 27 | Z6: 10 | AA6: 1 | AB6: 22 | AC6: 10 | AD6: =SUM(X6:AC6) -> 86 | AE6: =AD6*61 -> 5246 | AF6: 11 | AG6: 12 | AH6: 10 | AI6: 13 | AJ6: 10 | AK6: =SUM(AF6:AJ6) -> 56 | AL6: =AK6*61 -> 3416 | AS6: VITAOVO | AT6: =AO48 -> 793
B7: CONEJO | C7: - | D7: 17 | E7: 41 | F7: =SUM(C7:E7) -> 58 | G7: =F7*60 -> 3480 | H7: 5 | I7: 10 | J7: - | K7: 41 | L7: 10 | M7: 12 | N7: =SUM(H7:M7) -> 78 | O7: =N7*60 -> 4680 | P7: 10 | Q7: 11 | S7: - | T7: 1 | U7: - | V7: =SUM(P7:U7) -> 22 | W7: =V7*60 -> 1320 | X7: 5 | Y7: 31 | Z7: 6 | AA7: 30 | AB7: 28 | AC7: 15 | AD7: =SUM(X7:AC7) -> 115 | AE7: =AD7*60 -> 6900 | AF7: 7 | AG7: - | AH7: 17 | AI7: 10 | AJ7: 34 | AK7: =SUM(AF7:AJ7) -> 68 | AL7: =AK7*60 -> 4080 | AS7: VALOR M. | AT7: =AO49 -> 82697
B8: CUY | C8: - | D8: 20 | E8: 5 | F8: =SUM(C8:E8) -> 25 | G8: =F8*60 -> 1500 | H8: - | I8: 23 | J8: - | K8: 26 | L8: 34 | M8: 28 | N8: =SUM(H8:M8) -> 111 | O8: =N8*60 -> 6660 | P8: 1 | Q8: 15 | S8: 6 | T8: 1 | U8: - | V8: =SUM(P8:U8) -> 23 | W8: =V8*60 -> 1380 | X8: - | Y8: 35 | Z8: 6 | AA8: 20 | AB8: 16 | AC8: 10 | AD8: =SUM(X8:AC8) -> 87 | AE8: =AD8*60 -> 5220 | AF8: 8 | AG8: - | AH8: 12 | AI8: 15 | AJ8: 35 | AK8: =SUM(AF8:AJ8) -> 70 | AL8: =AK8*60 -> 4200 | AS8: AFRECHO | AT8: =AO51 -> 606
B9: CON POLLO | C9: - | D9: 23 | E9: 8 | F9: =SUM(C9:E9) -> 31 | G9: =F9*60 -> 1860 | H9: 18 | I9: 7 | J9: 3 | K9: 7 | L9: 15 | M9: 10 | N9: =SUM(H9:M9) -> 60 | O9: =N9*60 -> 3600 | P9: 1 | Q9: 2 | S9: 2 | T9: 2 | U9: - | V9: =SUM(P9:U9) -> 7 | W9: =V9*60 -> 420 | X9: 21 | Y9: 4 | Z9: 7 | AA9: - | AB9: 13 | AC9: - | AD9: =SUM(X9:AC9) -> 45 | AE9: =AD9*60 -> 2700 | AF9: 12 | AG9: 7 | AH9: 35 | AI9: 10 | AJ9: 20 | AK9: =SUM(AF9:AJ9) -> 84 | AL9: =AK9*60 -> 5040 | AS9: VALOR M. | AT9: =AO52 -> 35148
B10: CON CUY | C10: 6 | D10: 5 | E10: 15 | F10: =SUM(C10:E10) -> 26 | G10: =F10*60 -> 1560 | H10: 1 | I10: 15 | J10: - | K10: 21 | L10: 14 | M10: - | N10: =SUM(H10:M10) -> 51 | O10: =N10*60 -> 3060 | P10: - | Q10: - | S10: - | T10: 11 | U10: 9 | V10: =SUM(P10:U10) -> 20 | W10: =V10*60 -> 1200 | X10: 11 | Y10: 22 | Z10: 15 | AA10: - | AB10: 11 | AC10: - | AD10: =SUM(X10:AC10) -> 59 | AE10: =AD10*60 -> 3540 | AF10: 3 | AG10: 2 | AH10: 11 | AI10: - | AJ10: 36 | AK10: =SUM(AF10:AJ10) -> 52 | AL10: =AK10*60 -> 3120 | AS10: MAIZ | AT10: =AO58 -> 10227
B11: VERDE | C11: - | D11: 3 | E11: - | F11: =SUM(C11:E11) -> 3 | G11: =F11*65 -> 195 | H11: - | I11: 30 | J11: 1 | K11: 4 | L11: 2 | M11: 3 | N11: =SUM(H11:M11) -> 40 | O11: =N11*65 -> 2600 | P11: - | Q11: - | R11: 1 | S11: 3 | T11: 2 | U11: - | V11: =SUM(P11:U11) -> 6 | W11: =V11*65 -> 390 | X11: 10 | Y11: - | Z11: - | AA11: - | AB11: - | AC11: - | AD11: =SUM(X11:AC11) -> 10 | AE11: =AD11*65 -> 650 | AF11: - | AG11: 10 | AH11: 5 | AI11: - | AJ11: - | AK11: =SUM(AF11:AJ11) -> 15 | AL11: =AK11*65 -> 975 | AS11: VALOR M. | AT11: =AO59 -> 1067675
B12: ROJO | C12: - | D12: 3 | E12: - | F12: =SUM(C12:E12) -> 3 | G12: =F12*65 -> 195 | H12: - | I12: 1 | J12: 1 | K12: - | L12: 3 | M12: 3 | N12: =SUM(H12:M12) -> 8 | O12: =N12*65 -> 520 | P12: 1 | Q12: - | R12: 1 | S12: 2 | T12: - | U12: 1 | V12: =SUM(P12:U12) -> 5 | W12: =V12*65 -> 325 | X12: 6 | Y12: - | Z12: - | AA12: - | AB12: 2 | AC12: - | AD12: =SUM(X12:AC12) -> 8 | AE12: =AD12*65 -> 520 | AF12: - | AG12: - | AH12: 5 | AI12: - | AJ12: - | AK12: =SUM(AF12:AJ12) -> 5 | AL12: =AK12*65 -> 325 | AS12: TRIGO | AT12: =AO61 -> 1216
B13: POLLON | C13: - | D13: 13 | E13: 57 | F13: =SUM(C13:E13) -> 70 | G13: =F13*95 -> 6650 | H13: 5 | I13: 12 | J13: - | K13: 2 | L13: 24 | M13: 9 | N13: =SUM(H13:M13) -> 52 | O13: =N13*95 -> 4940 | P13: 76 | Q13: 78 | R13: 30 | S13: 10 | T13: 1 | U13: 10 | V13: =SUM(P13:U13) -> 205 | W13: =V13*95 -> 19475 | X13: 75 | Y13: 34 | Z13: 32 | AA13: - | AB13: 31 | AC13: 15 | AD13: =SUM(X13:AC13) -> 187 | AE13: =AD13*95 -> 17765 | AF13: 65 | AG13: 40 | AH13: 38 | AI13: 30 | AJ13: 31 | AK13: =SUM(AF13:AJ13) -> 204 | AL13: =AK13*95 -> 19380 | AS13: VALOR M. | AT13: =AO62 -> 121600
B14: CTO POLLON | C14: 20 | D14: 16 | E14: 46 | F14: =SUM(C14:E14) -> 82 | G14: =F14*105 -> 8610 | H14: 7 | I14: 15 | J14: - | K14: 16 | L14: 38 | M14: 16 | N14: =SUM(H14:M14) -> 92 | O14: =N14*105 -> 9660 | P14: 4 | Q14: 20 | R14: 20 | S14: 8 | T14: 7 | U14: 10 | V14: =SUM(P14:U14) -> 69 | W14: =V14*105 -> 7245 | X14: 50 | Y14: 3 | Z14: 2 | AA14: - | AB14: 25 | AC14: 15 | AD14: =SUM(X14:AC14) -> 95 | AE14: =AD14*105 -> 9975 | AF14: 42 | AG14: 30 | AH14: 52 | AI14: 31 | AJ14: 24 | AK14: =SUM(AF14:AJ14) -> 179 | AL14: =AK14*105 -> 18795
B15: INICIO POLLON | C15: 5 | D15: 4 | E15: 10 | F15: =SUM(C15:E15) -> 19 | G15: =F15*110 -> 2090 | H15: 2 | I15: 10 | J15: - | K15: 3 | L15: 10 | M15: 5 | N15: =SUM(H15:M15) -> 30 | O15: =N15*110 -> 3300 | P15: 4 | Q15: - | S15: - | T15: - | U15: - | V15: =SUM(P15:U15) -> 4 | W15: =V15*110 -> 440 | X15: 20 | Y15: 6 | Z15: 2 | AA15: - | AB15: - | AC15: 5 | AD15: =SUM(X15:AC15) -> 33 | AE15: =AD15*110 -> 3630 | AF15: 11 | AG15: - | AH15: 20 | AI15: - | AJ15: 5 | AK15: =SUM(AF15:AJ15) -> 36 | AL15: =AK15*110 -> 3960 | AS15: MAIZ B12 | AT15: 493380
B16: DORIMICYN | C16: - | D16: 1 | E16: 6 | F16: =SUM(C16:E16) -> 7 | G16: =F16*70 -> 490 | H16: - | I16: 2 | J16: - | K16: 15 | L16: 23 | M16: - | N16: =SUM(H16:M16) -> 40 | O16: =N16*70 -> 2800 | P16: 7 | Q16: - | R16: 6 | S16: 2 | T16: - | U16: - | V16: =SUM(P16:U16) -> 15 | W16: =V16*70 -> 1050 | X16: - | Y16: - | Z16: - | AA16: - | AB16: - | AD16: =SUM(X16:AC16) -> 0 | AE16: =AD16*70 -> 0 | AF16: 1 | AG16: 20 | AH16: 2 | AI16: 15 | AJ16: - | AK16: =SUM(AF16:AJ16) -> 38 | AL16: =AK16*70 -> 2660
B17: CTO SIMPLE | C17: - | D17: - | E17: - | F17: =SUM(C17:E17) -> 0 | G17: =F17*0 -> 0 | H17: - | J17: - | L17: - | M17: - | N17: =SUM(H17:M17) -> 0 | O17: =N17*0 -> 0 | Q17: - | T17: - | U17: - | V17: =SUM(P17:U17) -> 0 | W17: =V17*0 -> 0 | Y17: - | AA17: - | AB17: - | AD17: =SUM(X17:AC17) -> 0 | AE17: =AD17*0 -> 0 | AF17: - | AK17: =SUM(AF17:AJ17) -> 0 | AL17: =AK17*0 -> 0
B18: CTO ANA | C18: - | D18: - | E18: - | F18: =SUM(C18:E18) -> 0 | G18: =F18*0 -> 0 | H18: - | J18: - | L18: - | M18: - | N18: =SUM(H18:M18) -> 0 | O18: =N18*0 -> 0 | Q18: - | T18: - | U18: - | V18: =SUM(P18:U18) -> 0 | W18: =V18*0 -> 0 | Y18: - | AA18: - | AB18: - | AD18: =SUM(X18:AC18) -> 0 | AE18: =AD18*0 -> 0 | AF18: - | AK18: =SUM(AF18:AJ18) -> 0 | AL18: =AK18*0 -> 0
F19: =SUM(F4:F16) -> 518 | G19: =SUM(G4:G16) -> 38292 | N19: =SUM(N4:N16) -> 1000 | O19: =SUM(O4:O16) -> 68169 | V19: =SUM(V4:V16) -> 648 | W19: =SUM(W4:W16) -> 49622 | AD19: =SUM(AD4:AD16) -> 1097 | AE19: =SUM(AE4:AE16) -> 78466 | AK19: =SUM(AK4:AK16) -> 1246 | AL19: =SUM(AL4:AL16) -> 92291 | AN19: ALIMENTOS | AO19: =F50+N50+V50+AD50+AK50 -> 5992 | AP19: =AO20/AO19 -> 73.288718
B20: CTO BLANCO | D20: 2 | E20: - | F20: =SUM(C20:E20) -> 2 | G20: =F20*85 -> 170 | I20: 10 | K20: 20 | L20: 37 | M20: 16 | N20: =SUM(H20:M20) -> 83 | O20: =N20*85 -> 7055 | P20: 1 | Q20: 10 | R20: 5 | S20: 2 | T20: - | U20: - | V20: =SUM(P20:U20) -> 18 | W20: =V20*85 -> 1530 | AA20: 20 | AD20: =SUM(X20:AC20) -> 20 | AE20: =AD20*85 -> 1700 | AI20: 20 | AJ20: 15 | AK20: =SUM(AF20:AJ20) -> 35 | AL20: =AK20*85 -> 2975 | AN20: VALOR M. | AO20: =G50+O50+W50+AE50+AL50 -> 439146
B21: ENG BLANCO | D21: 5 | E21: 10 | F21: =SUM(C21:E21) -> 15 | G21: =F21*84 -> 1260 | H21: - | K21: 20 | L21: 24 | M21: 6 | N21: =SUM(H21:M21) -> 50 | O21: =N21*84 -> 4200 | P21: 1 | Q21: - | R21: 5 | S21: 2 | U21: 10 | V21: =SUM(P21:U21) -> 18 | W21: =V21*84 -> 1512 | AA21: 30 | AD21: =SUM(X21:AC21) -> 30 | AE21: =AD21*84 -> 2520 | AF21: 2 | AI21: 55 | AJ21: 20 | AK21: =SUM(AF21:AJ21) -> 77 | AL21: =AK21*84 -> 6468
B22: INICIO BLANCO | E22: - | F22: =SUM(C22:E22) -> 0 | G22: =F22*85 -> 0 | H22: - | I22: 1 | J22: 2 | K22: 15 | L22: 7 | M22: 12 | N22: =SUM(H22:M22) -> 37 | O22: =N22*85 -> 3145 | Q22: - | R22: 80 | S22: - | U22: 10 | V22: =SUM(P22:U22) -> 90 | W22: =V22*85 -> 7650 | AA22: - | AD22: =SUM(X22:AC22) -> 0 | AE22: =AD22*85 -> 0 | AF22: 1 | AI22: 13 | AK22: =SUM(AF22:AJ22) -> 14 | AL22: =AK22*85 -> 1190
B23: PRE BLANCO | E23: - | F23: =SUM(C23:E23) -> 0 | G23: =F23*85 -> 0 | H23: - | K23: - | L23: 21 | M23: 5 | N23: =SUM(H23:M23) -> 26 | O23: =N23*85 -> 2210 | P23: 1 | Q23: 5 | R23: 5 | S23: 4 | V23: =SUM(P23:U23) -> 15 | W23: =V23*85 -> 1275 | AA23: - | AC23: 5 | AD23: =SUM(X23:AC23) -> 5 | AE23: =AD23*85 -> 425 | AF23: 1 | AI23: - | AK23: =SUM(AF23:AJ23) -> 1 | AL23: =AK23*85 -> 85
B24: CTO AMARILLO | E24: - | F24: =SUM(C24:E24) -> 0 | G24: =F24*85 -> 0 | H24: - | K24: - | L24: - | N24: =SUM(H24:M24) -> 0 | O24: =N24*85 -> 0 | Q24: - | R24: 70 | V24: =SUM(P24:U24) -> 70 | W24: =V24*85 -> 5950 | AA24: - | AD24: =SUM(X24:AC24) -> 0 | AE24: =AD24*85 -> 0 | AG24: 25 | AI24: - | AK24: =SUM(AF24:AJ24) -> 25 | AL24: =AK24*85 -> 2125 | AN24: LINEA GALLO
B25: ENG AMARILLO | E25: - | F25: =SUM(C25:E25) -> 0 | G25: =F25*84 -> 0 | H25: 25 | L25: - | N25: =SUM(H25:M25) -> 25 | O25: =N25*84 -> 2100 | Q25: - | R25: 120 | V25: =SUM(P25:U25) -> 120 | W25: =V25*84 -> 10080 | AA25: - | AD25: =SUM(X25:AC25) -> 0 | AE25: =AD25*84 -> 0 | AG25: 40 | AI25: - | AK25: =SUM(AF25:AJ25) -> 40 | AL25: =AK25*84 -> 3360 | AN25: POLLON | AO25: =F13+N13+V13+AD13+AK13 -> 718
B26: INICIO AMARILLO | E26: - | F26: =SUM(C26:E26) -> 0 | G26: =F26*85 -> 0 | L26: - | N26: =SUM(H26:M26) -> 0 | O26: =N26*85 -> 0 | P26: 1 | Q26: - | R26: 28 | V26: =SUM(P26:U26) -> 29 | W26: =V26*85 -> 2465 | AA26: - | AD26: =SUM(X26:AC26) -> 0 | AE26: =AD26*85 -> 0 | AG26: 20 | AI26: - | AK26: =SUM(AF26:AJ26) -> 20 | AL26: =AK26*85 -> 1700 | AN26: POLLON CTO | AO26: =F14+N14+V14+AD14+AK14 -> 517
B27: PRE AMARILLO | E27: - | F27: =SUM(C27:E27) -> 0 | G27: =F27*85 -> 0 | L27: - | N27: =SUM(H27:M27) -> 0 | O27: =N27*85 -> 0 | Q27: - | V27: =SUM(P27:U27) -> 0 | W27: =V27*85 -> 0 | AA27: - | AD27: =SUM(X27:AC27) -> 0 | AE27: =AD27*85 -> 0 | AI27: - | AK27: =SUM(AF27:AJ27) -> 0 | AL27: =AK27*85 -> 0 | AN27: POLLON INICIO | AO27: =F15+N15+V15+AD15+AK15 -> 122
B28: CUY VITA | D28: 2 | E28: - | F28: =SUM(C28:E28) -> 2 | G28: =F28*75 -> 150 | L28: 10 | M28: 5 | N28: =SUM(H28:M28) -> 15 | O28: =N28*75 -> 1125 | Q28: - | U28: 15 | V28: =SUM(P28:U28) -> 15 | W28: =V28*75 -> 1125 | AA28: - | AD28: =SUM(X28:AC28) -> 0 | AE28: =AD28*75 -> 0 | AI28: - | AK28: =SUM(AF28:AJ28) -> 0 | AL28: =AK28*75 -> 0 | AO28: =SUM(AO25:AO27) -> 1357
B29: CONEJO VITA | D29: 2 | E29: - | F29: =SUM(C29:E29) -> 2 | G29: =F29*75 -> 150 | K29: 10 | L29: - | N29: =SUM(H29:M29) -> 10 | O29: =N29*75 -> 750 | P29: 1 | Q29: - | V29: =SUM(P29:U29) -> 1 | W29: =V29*75 -> 75 | AA29: - | AD29: =SUM(X29:AC29) -> 0 | AE29: =AD29*75 -> 0 | AG29: 5 | AI29: - | AK29: =SUM(AF29:AJ29) -> 5 | AL29: =AK29*75 -> 375
B30: POSTURA | D30: 4 | E30: 10 | F30: =SUM(C30:E30) -> 14 | G30: =F30*78 -> 1092 | I30: 2 | K30: 20 | L30: 3 | M30: 5 | N30: =SUM(H30:M30) -> 30 | O30: =N30*78 -> 2340 | P30: 2 | Q30: 7 | R30: 50 | S30: 8 | V30: =SUM(P30:U30) -> 67 | W30: =V30*78 -> 5226 | Z30: - | AA30: 20 | AC30: 15 | AD30: =SUM(X30:AC30) -> 35 | AE30: =AD30*78 -> 2730 | AF30: 1 | AG30: 35 | AH30: 10 | AI30: 15 | AJ30: 10 | AK30: =SUM(AF30:AJ30) -> 71 | AL30: =AK30*78 -> 5538
B31: POSTURA ECO. | E31: - | F31: =SUM(C31:E31) -> 0 | G31: =F31*70 -> 0 | L31: - | N31: =SUM(H31:M31) -> 0 | O31: =N31*70 -> 0 | V31: =SUM(P31:U31) -> 0 | W31: =V31*70 -> 0 | AD31: =SUM(X31:AC31) -> 0 | AE31: =AD31*70 -> 0 | AI31: - | AJ31: - | AK31: =SUM(AF31:AJ31) -> 0 | AL31: =AK31*70 -> 0
B32: ROJO PROVINCIA | E32: - | F32: =SUM(C32:E32) -> 0 | G32: =F32*60 -> 0 | L32: - | N32: =SUM(H32:M32) -> 0 | O32: =N32*60 -> 0 | V32: =SUM(P32:U32) -> 0 | W32: =V32*60 -> 0 | AD32: =SUM(X32:AC32) -> 0 | AE32: =AD32*60 -> 0 | AI32: - | AJ32: - | AK32: =SUM(AF32:AJ32) -> 0 | AL32: =AK32*60 -> 0
B33: VERDE PROVINCIA | E33: - | F33: =SUM(C33:E33) -> 0 | G33: =F33*60 -> 0 | L33: - | N33: =SUM(H33:M33) -> 0 | O33: =N33*60 -> 0 | V33: =SUM(P33:U33) -> 0 | W33: =V33*60 -> 0 | AD33: =SUM(X33:AC33) -> 0 | AE33: =AD33*60 -> 0 | AI33: - | AJ33: - | AK33: =SUM(AF33:AJ33) -> 0 | AL33: =AK33*60 -> 0
B34: ENG SIMPLE | E34: - | F34: =SUM(C34:E34) -> 0 | G34: =F34*40 -> 0 | L34: - | N34: =SUM(H34:M34) -> 0 | O34: =N34*40 -> 0 | V34: =SUM(P34:U34) -> 0 | W34: =V34*40 -> 0 | AD34: =SUM(X34:AC34) -> 0 | AE34: =AD34*40 -> 0 | AI34: - | AJ34: - | AK34: =SUM(AF34:AJ34) -> 0 | AL34: =AK34*40 -> 0
B35: CTO SIMPLE | D35: 8 | E35: - | F35: =SUM(C35:E35) -> 8 | G35: =F35*40 -> 320 | K35: 4 | L35: 70 | M35: 26 | N35: =SUM(H35:M35) -> 100 | O35: =N35*40 -> 4000 | P35: 25 | R35: 10 | S35: 10 | T35: 5 | V35: =SUM(P35:U35) -> 50 | W35: =V35*40 -> 2000 | X35: 5 | AA35: 10 | AB35: 10 | AD35: =SUM(X35:AC35) -> 25 | AE35: =AD35*40 -> 1000 | AF35: 1 | AG35: 40 | AH35: 20 | AI35: - | AJ35: - | AK35: =SUM(AF35:AJ35) -> 61 | AL35: =AK35*40 -> 2440
B36: GRANJA X 40 KG | E36: - | F36: =SUM(C36:E36) -> 0 | G36: =F36*76 -> 0 | L36: 47 | N36: =SUM(H36:M36) -> 47 | O36: =N36*76 -> 3572 | V36: =SUM(P36:U36) -> 0 | W36: =V36*76 -> 0 | AD36: =SUM(X36:AC36) -> 0 | AE36: =AD36*76 -> 0 | AI36: 30 | AK36: =SUM(AF36:AJ36) -> 30 | AL36: =AK36*76 -> 2280
B37: GRANJA X 50 KG | E37: - | F37: =SUM(C37:E37) -> 0 | G37: =F37*90 -> 0 | N37: =SUM(H37:M37) -> 0 | O37: =N37*90 -> 0 | V37: =SUM(P37:U37) -> 0 | W37: =V37*90 -> 0 | AD37: =SUM(X37:AC37) -> 0 | AE37: =AD37*90 -> 0 | AI37: - | AJ37: - | AK37: =SUM(AF37:AJ37) -> 0 | AL37: =AK37*90 -> 0
B38: CTO CON. POLLO | E38: - | F38: =SUM(C38:E38) -> 0 | G38: =F38*91 -> 0 | N38: =SUM(H38:M38) -> 0 | O38: =N38*91 -> 0 | V38: =SUM(P38:U38) -> 0 | W38: =V38*91 -> 0 | AD38: =SUM(X38:AC38) -> 0 | AE38: =AD38*91 -> 0 | AI38: - | AJ38: - | AK38: =SUM(AF38:AJ38) -> 0 | AL38: =AK38*91 -> 0
B39: ENG CON. POLLO | E39: - | F39: =SUM(C39:E39) -> 0 | G39: =F39*90 -> 0 | N39: =SUM(H39:M39) -> 0 | O39: =N39*90 -> 0 | V39: =SUM(P39:U39) -> 0 | W39: =V39*90 -> 0 | AD39: =SUM(X39:AC39) -> 0 | AE39: =AD39*90 -> 0 | AK39: =SUM(AF39:AJ39) -> 0 | AL39: =AK39*90 -> 0
B40: CERDO MANTTO | E40: - | F40: =SUM(C40:E40) -> 0 | G40: =F40*76 -> 0 | N40: =SUM(H40:M40) -> 0 | O40: =N40*76 -> 0 | V40: =SUM(P40:U40) -> 0 | W40: =V40*76 -> 0 | AD40: =SUM(X40:AC40) -> 0 | AE40: =AD40*76 -> 0 | AK40: =SUM(AF40:AJ40) -> 0 | AL40: =AK40*76 -> 0
B41: CTO CERDO | E41: - | F41: =SUM(C41:E41) -> 0 | G41: =F41*100 -> 0 | K41: 12 | N41: =SUM(H41:M41) -> 12 | O41: =N41*100 -> 1200 | V41: =SUM(P41:U41) -> 0 | W41: =V41*100 -> 0 | AD41: =SUM(X41:AC41) -> 0 | AE41: =AD41*100 -> 0 | AK41: =SUM(AF41:AJ41) -> 0 | AL41: =AK41*100 -> 0
B42: ENG CERDO | E42: - | F42: =SUM(C42:E42) -> 0 | G42: =F42*100 -> 0 | K42: 12 | N42: =SUM(H42:M42) -> 12 | O42: =N42*100 -> 1200 | V42: =SUM(P42:U42) -> 0 | W42: =V42*100 -> 0 | AD42: =SUM(X42:AC42) -> 0 | AE42: =AD42*100 -> 0 | AK42: =SUM(AF42:AJ42) -> 0 | AL42: =AK42*100 -> 0
...

Sheet FEBRERO
B3: ALIMENTO | C3: 45689 | D3: SUB TOTAL | E3: MONTO | F3: 45691 | G3: 45692 | H3: 45693 | I3: 45694 | J3: 45695 | K3: 45696 | L3: SUB TOTAL | M3: MONTO | N3: 45698 | O3: 45699 | P3: 45700 | Q3: 45701 | R3: 45702 | S3: 45703 | T3: SUB TOTAL | U3: MONTO | V3: 45705 | W3: 45706 | X3: 45707 | Y3: 45708 | Z3: 45709 | AA3: 45710 | AB3: SUB TOTAL | AC3: MONTO | AD3: 45712 | AE3: 45713 | AF3: 45714 | AG3: 45715 | AH3: 45716 | AI3: SUB TOTAL | AJ3: MONTO | AQ3: MES : FEBRERO
B4: ENG CARNE | C4: 16 | D4: =SUM(C4:C4) -> 16 | E4: =D4*60 -> 960 | F4: 52 | G4: 36 | H4: 20 | I4: 48 | J4: - | K4: 15 | L4: =SUM(F4:K4) -> 171 | M4: =L4*60 -> 10260 | N4: 115 | O4: 8 | P4: 30 | Q4: 15 | R4: 60 | S4: 10 | T4: =SUM(N4:S4) -> 238 | U4: =T4*60 -> 14280 | V4: 34 | W4: 40 | X4: 30 | Y4: 75 | Z4: 13 | AA4: 10 | AB4: =SUM(V4:AA4) -> 202 | AC4: =AB4*60 -> 12120 | AD4: 17 | AE4: 45 | AF4: 50 | AG4: - | AH4: 22 | AI4: =SUM(AD4:AH4) -> 134 | AJ4: =AI4*60 -> 8040 | AQ4: ALIMENTOS | AR4: =AM19 -> 4882
B5: CTO CARNE | C5: 10 | D5: =SUM(C5:C5) -> 10 | E5: =D5*60 -> 600 | F5: 30 | G5: 46 | H5: 13 | I5: 20 | J5: - | L5: =SUM(F5:K5) -> 109 | M5: =L5*60 -> 6540 | N5: 64 | O5: 22 | P5: 30 | Q5: 27 | R5: 45 | S5: 5 | T5: =SUM(N5:S5) -> 193 | U5: =T5*60 -> 11580 | V5: 38 | W5: 52 | X5: 60 | Y5: 41 | Z5: - | AA5: 9 | AB5: =SUM(V5:AA5) -> 200 | AC5: =AB5*60 -> 12000 | AD5: 16 | AE5: 32 | AF5: 50 | AG5: - | AH5: 25 | AI5: =SUM(AD5:AH5) -> 123 | AJ5: =AI5*60 -> 7380 | AQ5: VALOR M. | AR5: =AM20 -> 357236
B6: INICIO CARNE | C6: 1 | D6: =SUM(C6:C6) -> 1 | E6: =D6*61 -> 61 | F6: - | G6: 1 | H6: 1 | I6: 10 | J6: 9 | K6: 2 | L6: =SUM(F6:K6) -> 23 | M6: =L6*61 -> 1403 | N6: 51 | O6: 1 | P6: 15 | Q6: 1 | R6: 25 | S6: 5 | T6: =SUM(N6:S6) -> 98 | U6: =T6*61 -> 5978 | V6: 2 | W6: 27 | X6: 10 | Y6: 25 | Z6: - | AB6: =SUM(V6:AA6) -> 64 | AC6: =AB6*61 -> 3904 | AD6: 6 | AE6: 11 | AF6: 11 | AG6: - | AH6: 5 | AI6: =SUM(AD6:AH6) -> 33 | AJ6: =AI6*61 -> 2013 | AQ6: VITAOVO | AR6: =AM48 -> 653
B7: CONEJO | C7: - | D7: =SUM(C7:C7) -> 0 | E7: =D7*60 -> 0 | F7: - | G7: 1 | H7: - | I7: 10 | J7: 12 | L7: =SUM(F7:K7) -> 23 | M7: =L7*60 -> 1380 | N7: 16 | O7: 26 | P7: 25 | Q7: 5 | R7: 20 | S7: 5 | T7: =SUM(N7:S7) -> 97 | U7: =T7*60 -> 5820 | V7: 22 | W7: 25 | X7: 15 | Y7: - | Z7: - | AB7: =SUM(V7:AA7) -> 62 | AC7: =AB7*60 -> 3720 | AD7: 18 | AE7: 1 | AF7: 15 | AG7: - | AH7: 10 | AI7: =SUM(AD7:AH7) -> 44 | AJ7: =AI7*60 -> 2640 | AQ7: VALOR M. | AR7: =AM49 -> 68144
B8: CUY | D8: =SUM(C8:C8) -> 0 | E8: =D8*60 -> 0 | F8: 15 | G8: 1 | H8: - | I8: 15 | J8: 4 | L8: =SUM(F8:K8) -> 35 | M8: =L8*60 -> 2100 | N8: 57 | O8: 19 | P8: 20 | Q8: - | R8: 20 | S8: - | T8: =SUM(N8:S8) -> 116 | U8: =T8*60 -> 6960 | V8: 11 | W8: 45 | X8: 5 | Y8: 10 | Z8: - | AB8: =SUM(V8:AA8) -> 71 | AC8: =AB8*60 -> 4260 | AD8: 22 | AE8: 4 | AF8: 5 | AG8: - | AH8: 5 | AI8: =SUM(AD8:AH8) -> 36 | AJ8: =AI8*60 -> 2160 | AQ8: AFRECHO | AR8: =AM51 -> 427
B9: CON POLLO | D9: =SUM(C9:C9) -> 0 | E9: =D9*60 -> 0 | F9: - | G9: 23 | H9: 28 | I9: 2 | J9: - | K9: 1 | L9: =SUM(F9:K9) -> 54 | M9: =L9*60 -> 3240 | N9: 150 | O9: 18 | P9: 2 | Q9: 6 | R9: 10 | S9: 6 | T9: =SUM(N9:S9) -> 192 | U9: =T9*60 -> 11520 | V9: 13 | W9: 31 | X9: 4 | Y9: - | Z9: - | AA9: 1 | AB9: =SUM(V9:AA9) -> 49 | AC9: =AB9*60 -> 2940 | AD9: 10 | AE9: 23 | AF9: - | AG9: - | AH9: - | AI9: =SUM(AD9:AH9) -> 33 | AJ9: =AI9*60 -> 1980 | AQ9: VALOR M. | AR9: =AM52 -> 24766
B10: CON CUY | D10: =SUM(C10:C10) -> 0 | E10: =D10*60 -> 0 | F10: - | G10: 5 | H10: 5 | I10: 1 | J10: 1 | L10: =SUM(F10:K10) -> 12 | M10: =L10*60 -> 720 | N10: 16 | O10: 21 | P10: - | Q10: 5 | R10: 15 | S10: 17 | T10: =SUM(N10:S10) -> 74 | U10: =T10*60 -> 4440 | V10: 7 | X10: 17 | Y10: 1 | Z10: - | AB10: =SUM(V10:AA10) -> 25 | AC10: =AB10*60 -> 1500 | AD10: 12 | AE10: 13 | AF10: - | AG10: - | AH10: - | AI10: =SUM(AD10:AH10) -> 25 | AJ10: =AI10*60 -> 1500 | AQ10: MAIZ | AR10: =AM58 -> 7369
B11: VERDE | D11: =SUM(C11:C11) -> 0 | E11: =D11*65 -> 0 | F11: - | G11: 3 | H11: - | I11: - | J11: - | L11: =SUM(F11:K11) -> 3 | M11: =L11*65 -> 195 | N11: - | O11: - | P11: 8 | Q11: - | R11: - | S11: - | T11: =SUM(N11:S11) -> 8 | U11: =T11*65 -> 520 | V11: 2 | X11: 9 | Y11: - | Z11: - | AB11: =SUM(V11:AA11) -> 11 | AC11: =AB11*65 -> 715 | AD11: 5 | AE11: - | AF11: 1 | AG11: 3 | AH11: 2 | AI11: =SUM(AD11:AH11) -> 11 | AJ11: =AI11*65 -> 715 | AQ11: VALOR M. | AR11: =AM59 -> 747985
B12: ROJO | C12: 3 | D12: =SUM(C12:C12) -> 3 | E12: =D12*65 -> 195 | F12: 1 | G12: 7 | H12: - | I12: - | J12: 3 | L12: =SUM(F12:K12) -> 11 | M12: =L12*65 -> 715 | N12: - | O12: - | P12: 5 | Q12: - | R12: - | S12: - | T12: =SUM(N12:S12) -> 5 | U12: =T12*65 -> 325 | V12: 2 | W12: 1 | X12: 9 | Y12: 2 | Z12: - | AA12: 1 | AB12: =SUM(V12:AA12) -> 15 | AC12: =AB12*65 -> 975 | AD12: - | AE12: 1 | AF12: 1 | AG12: - | AH12: - | AI12: =SUM(AD12:AH12) -> 2 | AJ12: =AI12*65 -> 130 | AQ12: TRIGO | AR12: =AM61 -> 1227
B13: POLLON | C13: 11 | D13: =SUM(C13:C13) -> 11 | E13: =D13*95 -> 1045 | F13: 50 | G13: 62 | H13: 55 | I13: 13 | J13: 18 | K13: 35 | L13: =SUM(F13:K13) -> 233 | M13: =L13*95 -> 22135 | N13: 69 | O13: 7 | P13: 10 | Q13: 60 | R13: 9 | S13: 5 | T13: =SUM(N13:S13) -> 160 | U13: =T13*95 -> 15200 | V13: 48 | W13: 30 | X13: 8 | Y13: 51 | Z13: 13 | AB13: =SUM(V13:AA13) -> 150 | AC13: =AB13*95 -> 14250 | AD13: 23 | AE13: 25 | AF13: 30 | AG13: - | AH13: 10 | AI13: =SUM(AD13:AH13) -> 88 | AJ13: =AI13*95 -> 8360 | AQ13: VALOR M. | AR13: =AM62 -> 122700
B14: CTO POLLON | C14: 10 | D14: =SUM(C14:C14) -> 10 | E14: =D14*105 -> 1050 | F14: 40 | G14: 56 | H14: 48 | I14: 28 | J14: 12 | L14: =SUM(F14:K14) -> 184 | M14: =L14*105 -> 19320 | N14: 20 | O14: 8 | P14: - | Q14: 45 | R14: 10 | S14: 16 | T14: =SUM(N14:S14) -> 99 | U14: =T14*105 -> 10395 | V14: 52 | W14: 16 | X14: 5 | Y14: 54 | Z14: 5 | AB14: =SUM(V14:AA14) -> 132 | AC14: =AB14*105 -> 13860 | AD14: 35 | AE14: 8 | AG14: - | AH14: 15 | AI14: =SUM(AD14:AH14) -> 58 | AJ14: =AI14*105 -> 6090
B15: INICIO POLLON | D15: =SUM(C15:C15) -> 0 | E15: =D15*110 -> 0 | F15: 10 | G15: 26 | H15: 20 | I15: 1 | J15: 6 | L15: =SUM(F15:K15) -> 63 | M15: =L15*110 -> 6930 | N15: - | O15: 1 | P15: 4 | Q15: 15 | R15: 6 | S15: - | T15: =SUM(N15:S15) -> 26 | U15: =T15*110 -> 2860 | V15: 4 | W15: 3 | X15: 3 | Y15: 16 | Z15: - | AB15: =SUM(V15:AA15) -> 26 | AC15: =AB15*110 -> 2860 | AD15: 2 | AE15: 3 | AG15: - | AH15: - | AI15: =SUM(AD15:AH15) -> 5 | AJ15: =AI15*110 -> 550 | AQ15: MAIZ B12 | AR15: 340170
B16: DORIMICYN | C16: 2 | D16: =SUM(C16:C16) -> 2 | E16: =D16*70 -> 140 | G16: 1 | H16: 1 | I16: - | J16: 2 | L16: =SUM(F16:K16) -> 4 | M16: =L16*70 -> 280 | N16: 1 | O16: - | P16: 10 | Q16: - | R16: - | S16: 2 | T16: =SUM(N16:S16) -> 13 | U16: =T16*70 -> 910 | V16: - | W16: 30 | X16: 11 | Y16: 5 | AB16: =SUM(V16:AA16) -> 46 | AC16: =AB16*70 -> 3220 | AD16: 20 | AE16: 1 | AF16: 18 | AG16: - | AH16: - | AI16: =SUM(AD16:AH16) -> 39 | AJ16: =AI16*70 -> 2730
B17: CTO SIMPLE | C17: - | D17: =SUM(C17:C17) -> 0 | E17: =D17*0 -> 0 | G17: - | I17: - | L17: =SUM(F17:K17) -> 0 | M17: =L17*0 -> 0 | N17: - | R17: - | S17: - | T17: =SUM(N17:S17) -> 0 | U17: =T17*0 -> 0 | AB17: =SUM(V17:AA17) -> 0 | AC17: =AB17*0 -> 0 | AG17: - | AI17: =SUM(AD17:AH17) -> 0 | AJ17: =AI17*0 -> 0
B18: CTO ANA | C18: - | D18: =SUM(C18:C18) -> 0 | E18: =D18*0 -> 0 | G18: - | I18: - | L18: =SUM(F18:K18) -> 0 | M18: =L18*0 -> 0 | N18: - | R18: - | S18: - | T18: =SUM(N18:S18) -> 0 | U18: =T18*0 -> 0 | W18: - | Y18: - | Z18: - | AB18: =SUM(V18:AA18) -> 0 | AC18: =AB18*0 -> 0 | AD18: - | AG18: - | AI18: =SUM(AD18:AH18) -> 0 | AJ18: =AI18*0 -> 0
D19: =SUM(D4:D16) -> 53 | E19: =SUM(E4:E16) -> 4051 | L19: =SUM(L4:L16) -> 925 | M19: =SUM(M4:M16) -> 75218 | T19: =SUM(T4:T16) -> 1319 | U19: =SUM(U4:U16) -> 90788 | AB19: =SUM(AB4:AB16) -> 1053 | AC19: =SUM(AC4:AC16) -> 76324 | AI19: =SUM(AI4:AI16) -> 631 | AJ19: =SUM(AJ4:AJ16) -> 44288 | AL19: ALIMENTOS | AM19: =D50+L50+T50+AB50+AI50 -> 4882 | AN19: =AM20/AM19 -> 73.174109
B20: CTO BLANCO | D20: =SUM(C20:C20) -> 0 | E20: =D20*85 -> 0 | G20: 8 | H20: 3 | I20: - | L20: =SUM(F20:K20) -> 11 | M20: =L20*85 -> 935 | O20: - | P20: 15 | Q20: - | R20: 50 | S20: - | T20: =SUM(N20:S20) -> 65 | U20: =T20*85 -> 5525 | W20: 20 | X20: 17 | AB20: =SUM(V20:AA20) -> 37 | AC20: =AB20*85 -> 3145 | AD20: 25 | AG20: - | AH20: 5 | AI20: =SUM(AD20:AH20) -> 30 | AJ20: =AI20*85 -> 2550 | AL20: VALOR M. | AM20: =E50+M50+U50+AC50+AJ50 -> 357236
B21: ENG BLANCO | D21: =SUM(C21:C21) -> 0 | E21: =D21*84 -> 0 | G21: 6 | H21: - | I21: 10 | L21: =SUM(F21:K21) -> 16 | M21: =L21*84 -> 1344 | O21: - | P21: - | R21: 60 | S21: - | T21: =SUM(N21:S21) -> 60 | U21: =T21*84 -> 5040 | W21: 5 | X21: 35 | Y21: 5 | AB21: =SUM(V21:AA21) -> 45 | AC21: =AB21*84 -> 3780 | AD21: 24 | AG21: - | AH21: - | AI21: =SUM(AD21:AH21) -> 24 | AJ21: =AI21*84 -> 2016
B22: INICIO BLANCO | D22: =SUM(C22:C22) -> 0 | E22: =D22*85 -> 0 | G22: 14 | H22: 2 | I22: - | L22: =SUM(F22:K22) -> 16 | M22: =L22*85 -> 1360 | N22: 10 | O22: - | P22: - | R22: - | S22: - | T22: =SUM(N22:S22) -> 10 | U22: =T22*85 -> 850 | W22: 10 | X22: 15 | AB22: =SUM(V22:AA22) -> 25 | AC22: =AB22*85 -> 2125 | AD22: 15 | AE22: 1 | AF22: 5 | AG22: - | AH22: - | AI22: =SUM(AD22:AH22) -> 21 | AJ22: =AI22*85 -> 1785
B23: PRE BLANCO | D23: =SUM(C23:C23) -> 0 | E23: =D23*85 -> 0 | G23: 1 | H23: 1 | I23: - | L23: =SUM(F23:K23) -> 2 | M23: =L23*85 -> 170 | O23: 10 | P23: - | T23: =SUM(N23:S23) -> 10 | U23: =T23*85 -> 850 | W23: 8 | X23: 15 | Y23: 20 | AB23: =SUM(V23:AA23) -> 43 | AC23: =AB23*85 -> 3655 | AD23: - | AG23: - | AH23: 7 | AI23: =SUM(AD23:AH23) -> 7 | AJ23: =AI23*85 -> 595
B24: CTO AMARILLO | D24: =SUM(C24:C24) -> 0 | E24: =D24*85 -> 0 | G24: 1 | I24: - | L24: =SUM(F24:K24) -> 1 | M24: =L24*85 -> 85 | O24: 1 | P24: - | T24: =SUM(N24:S24) -> 1 | U24: =T24*85 -> 85 | W24: - | Y24: 5 | AB24: =SUM(V24:AA24) -> 5 | AC24: =AB24*85 -> 425 | AD24: - | AG24: - | AH24: - | AI24: =SUM(AD24:AH24) -> 0 | AJ24: =AI24*85 -> 0 | AL24: LINEA GALLO
B25: ENG AMARILLO | D25: =SUM(C25:C25) -> 0 | E25: =D25*84 -> 0 | G25: - | I25: - | L25: =SUM(F25:K25) -> 0 | M25: =L25*84 -> 0 | O25: - | P25: 10 | T25: =SUM(N25:S25) -> 10 | U25: =T25*84 -> 840 | W25: 10 | AB25: =SUM(V25:AA25) -> 10 | AC25: =AB25*84 -> 840 | AD25: 15 | AG25: - | AH25: - | AI25: =SUM(AD25:AH25) -> 15 | AJ25: =AI25*84 -> 1260 | AL25: POLLON | AM25: =D13+L13+T13+AB13+AI13 -> 642
B26: INICIO AMARILLO | D26: =SUM(C26:C26) -> 0 | E26: =D26*85 -> 0 | G26: 1 | I26: - | L26: =SUM(F26:K26) -> 1 | M26: =L26*85 -> 85 | O26: - | P26: - | T26: =SUM(N26:S26) -> 0 | U26: =T26*85 -> 0 | W26: - | Y26: 10 | AB26: =SUM(V26:AA26) -> 10 | AC26: =AB26*85 -> 850 | AD26: 5 | AG26: - | AH26: - | AI26: =SUM(AD26:AH26) -> 5 | AJ26: =AI26*85 -> 425 | AL26: POLLON CTO | AM26: =D14+L14+T14+AB14+AI14 -> 483
B27: PRE AMARILLO | D27: =SUM(C27:C27) -> 0 | E27: =D27*85 -> 0 | I27: - | L27: =SUM(F27:K27) -> 0 | M27: =L27*85 -> 0 | O27: - | P27: - | T27: =SUM(N27:S27) -> 0 | U27: =T27*85 -> 0 | W27: - | AB27: =SUM(V27:AA27) -> 0 | AC27: =AB27*85 -> 0 | AG27: - | AH27: - | AI27: =SUM(AD27:AH27) -> 0 | AJ27: =AI27*85 -> 0 | AL27: POLLON INICIO | AM27: =D15+L15+T15+AB15+AI15 -> 120
B28: CUY VITA | D28: =SUM(C28:C28) -> 0 | E28: =D28*75 -> 0 | G28: 11 | I28: - | L28: =SUM(F28:K28) -> 11 | M28: =L28*75 -> 825 | N28: 11 | O28: - | P28: - | T28: =SUM(N28:S28) -> 11 | U28: =T28*75 -> 825 | W28: - | X28: 13 | AA28: 5 | AB28: =SUM(V28:AA28) -> 18 | AC28: =AB28*75 -> 1350 | AG28: - | AH28: 10 | AI28: =SUM(AD28:AH28) -> 10 | AJ28: =AI28*75 -> 750 | AM28: =SUM(AM25:AM27) -> 1245
B29: CONEJO VITA | D29: =SUM(C29:C29) -> 0 | E29: =D29*75 -> 0 | F29: 7 | I29: - | L29: =SUM(F29:K29) -> 7 | M29: =L29*75 -> 525 | O29: - | P29: - | T29: =SUM(N29:S29) -> 0 | U29: =T29*75 -> 0 | W29: - | AB29: =SUM(V29:AA29) -> 0 | AC29: =AB29*75 -> 0 | AD29: 10 | AG29: - | AI29: =SUM(AD29:AH29) -> 10 | AJ29: =AI29*75 -> 750
B30: POSTURA | D30: =SUM(C30:C30) -> 0 | E30: =D30*78 -> 0 | G30: 11 | H30: 4 | I30: 10 | L30: =SUM(F30:K30) -> 25 | M30: =L30*78 -> 1950 | N30: 3 | O30: 5 | P30: 8 | R30: 6 | T30: =SUM(N30:S30) -> 22 | U30: =T30*78 -> 1716 | V30: 2 | W30: 21 | X30: 5 | Y30: 7 | AB30: =SUM(V30:AA30) -> 35 | AC30: =AB30*78 -> 2730 | AE30: 7 | AF30: 10 | AG30: - | AI30: =SUM(AD30:AH30) -> 17 | AJ30: =AI30*78 -> 1326
B31: POSTURA ECO. | D31: =SUM(C31:C31) -> 0 | E31: =D31*70 -> 0 | L31: =SUM(F31:K31) -> 0 | M31: =L31*70 -> 0 | P31: - | T31: =SUM(N31:S31) -> 0 | U31: =T31*70 -> 0 | W31: - | AB31: =SUM(V31:AA31) -> 0 | AC31: =AB31*70 -> 0 | AG31: - | AI31: =SUM(AD31:AH31) -> 0 | AJ31: =AI31*70 -> 0
B32: ROJO PROVINCIA | D32: =SUM(C32:C32) -> 0 | E32: =D32*60 -> 0 | L32: =SUM(F32:K32) -> 0 | M32: =L32*60 -> 0 | P32: - | T32: =SUM(N32:S32) -> 0 | U32: =T32*60 -> 0 | AB32: =SUM(V32:AA32) -> 0 | AC32: =AB32*60 -> 0 | AF32: - | AG32: - | AH32: - | AI32: =SUM(AD32:AH32) -> 0 | AJ32: =AI32*60 -> 0
B33: VERDE PROVINCIA | D33: =SUM(C33:C33) -> 0 | E33: =D33*60 -> 0 | L33: =SUM(F33:K33) -> 0 | M33: =L33*60 -> 0 | P33: - | T33: =SUM(N33:S33) -> 0 | U33: =T33*60 -> 0 | AB33: =SUM(V33:AA33) -> 0 | AC33: =AB33*60 -> 0 | AG33: - | AI33: =SUM(AD33:AH33) -> 0 | AJ33: =AI33*60 -> 0
B34: ENG SIMPLE | D34: =SUM(C34:C34) -> 0 | E34: =D34*40 -> 0 | L34: =SUM(F34:K34) -> 0 | M34: =L34*40 -> 0 | P34: - | T34: =SUM(N34:S34) -> 0 | U34: =T34*40 -> 0 | AB34: =SUM(V34:AA34) -> 0 | AC34: =AB34*40 -> 0 | AG34: - | AI34: =SUM(AD34:AH34) -> 0 | AJ34: =AI34*40 -> 0
B35: CTO SIMPLE | C35: 20 | D35: =SUM(C35:C35) -> 20 | E35: =D35*40 -> 800 | H35: 30 | J35: 24 | L35: =SUM(F35:K35) -> 54 | M35: =L35*40 -> 2160 | P35: - | T35: =SUM(N35:S35) -> 0 | U35: =T35*40 -> 0 | V35: 6 | X35: 40 | AB35: =SUM(V35:AA35) -> 46 | AC35: =AB35*40 -> 1840 | AD35: 3 | AE35: 2 | AF35: 60 | AG35: - | AI35: =SUM(AD35:AH35) -> 65 | AJ35: =AI35*40 -> 2600
B36: GRANJA X 40 KG | D36: =SUM(C36:C36) -> 0 | E36: =D36*76 -> 0 | L36: =SUM(F36:K36) -> 0 | M36: =L36*76 -> 0 | P36: - | T36: =SUM(N36:S36) -> 0 | U36: =T36*76 -> 0 | W36: 50 | AB36: =SUM(V36:AA36) -> 50 | AC36: =AB36*76 -> 3800 | AG36: - | AI36: =SUM(AD36:AH36) -> 0 | AJ36: =AI36*76 -> 0
B37: GRANJA X 50 KG | D37: =SUM(C37:C37) -> 0 | E37: =D37*90 -> 0 | L37: =SUM(F37:K37) -> 0 | M37: =L37*90 -> 0 | P37: - | T37: =SUM(N37:S37) -> 0 | U37: =T37*90 -> 0 | AB37: =SUM(V37:AA37) -> 0 | AC37: =AB37*90 -> 0 | AG37: - | AI37: =SUM(AD37:AH37) -> 0 | AJ37: =AI37*90 -> 0
B38: CTO CON. POLLO | D38: =SUM(C38:C38) -> 0 | E38: =D38*91 -> 0 | L38: =SUM(F38:K38) -> 0 | M38: =L38*91 -> 0 | P38: - | T38: =SUM(N38:S38) -> 0 | U38: =T38*91 -> 0 | AB38: =SUM(V38:AA38) -> 0 | AC38: =AB38*91 -> 0 | AG38: - | AI38: =SUM(AD38:AH38) -> 0 | AJ38: =AI38*91 -> 0
B39: ENG CON. POLLO | D39: =SUM(C39:C39) -> 0 | E39: =D39*90 -> 0 | L39: =SUM(F39:K39) -> 0 | M39: =L39*90 -> 0 | P39: - | T39: =SUM(N39:S39) -> 0 | U39: =T39*90 -> 0 | AB39: =SUM(V39:AA39) -> 0 | AC39: =AB39*90 -> 0 | AG39: - | AI39: =SUM(AD39:AH39) -> 0 | AJ39: =AI39*90 -> 0
B40: CERDO MANTTO | D40: =SUM(C40:C40) -> 0 | E40: =D40*76 -> 0 | L40: =SUM(F40:K40) -> 0 | M40: =L40*76 -> 0 | P40: - | T40: =SUM(N40:S40) -> 0 | U40: =T40*76 -> 0 | AB40: =SUM(V40:AA40) -> 0 | AC40: =AB40*76 -> 0 | AG40: - | AI40: =SUM(AD40:AH40) -> 0 | AJ40: =AI40*76 -> 0
B41: CTO CERDO | D41: =SUM(C41:C41) -> 0 | E41: =D41*100 -> 0 | L41: =SUM(F41:K41) -> 0 | M41: =L41*100 -> 0 | P41: - | T41: =SUM(N41:S41) -> 0 | U41: =T41*100 -> 0 | W41: 10 | AB41: =SUM(V41:AA41) -> 10 | AC41: =AB41*100 -> 1000 | AG41: - | AI41: =SUM(AD41:AH41) -> 0 | AJ41: =AI41*100 -> 0
B42: ENG CERDO | D42: =SUM(C42:C42) -> 0 | E42: =D42*100 -> 0 | L42: =SUM(F42:K42) -> 0 | M42: =L42*100 -> 0 | P42: - | T42: =SUM(N42:S42) -> 0 | U42: =T42*100 -> 0 | W42: 10 | AB42: =SUM(V42:AA42) -> 10 | AC42: =AB42*100 -> 1000 | AG42: - | AI42: =SUM(AD42:AH42) -> 0 | AJ42: =AI42*100 -> 0
...

Sheet MARZO
B3: ALIMENTO | C3: 45717 | D3: SUB TOTAL | E3: MONTO | F3: 45719 | G3: 45720 | H3: 45721 | I3: 45722 | J3: 45723 | K3: 45724 | L3: SUB TOTAL | M3: MONTO | N3: 45726 | O3: 45727 | P3: 45728 | Q3: 45729 | R3: 45730 | S3: 45731 | T3: SUB TOTAL | U3: MONTO | V3: 45733 | W3: 45734 | X3: 45735 | Y3: 45736 | Z3: 45737 | AA3: 45738 | AB3: SUB TOTAL | AC3: MONTO | AD3: 45740 | AE3: 45741 | AF3: 45742 | AG3: 45743 | AH3: 45744 | AI3: 45745 | AJ3: 45747 | AK3: SUB TOTAL | AL3: MONTO | AS3: MES : MARZO
B4: ENG CARNE | C4: - | D4: =SUM(C4:C4) -> 0 | E4: =D4*60 -> 0 | F4: 3 | G4: 22 | H4: 60 | I4: 79 | J4: 83 | K4: 15 | L4: =SUM(F4:K4) -> 262 | M4: =L4*60 -> 15720 | N4: 68 | O4: 15 | P4: 35 | Q4: 10 | R4: 10 | S4: 67 | T4: =SUM(N4:S4) -> 205 | U4: =T4*60 -> 12300 | V4: - | W4: 26 | X4: 47 | Y4: 42 | Z4: 45 | AA4: 5 | AB4: =SUM(V4:AA4) -> 165 | AC4: =AB4*60 -> 9900 | AD4: 20 | AE4: 78 | AF4: 50 | AG4: 3 | AH4: 42 | AI4: 55 | AJ4: 25 | AK4: =SUM(AD4:AJ4) -> 273 | AL4: =AK4*60 -> 16380 | AS4: ALIMENTOS | AT4: =AO19 -> 6162
B5: CTO CARNE | C5: 16 | D5: =SUM(C5:C5) -> 16 | E5: =D5*60 -> 960 | F5: 14 | G5: 16 | H5: 55 | I5: 49 | J5: 90 | K5: 15 | L5: =SUM(F5:K5) -> 239 | M5: =L5*60 -> 14340 | N5: 33 | O5: 15 | P5: 25 | Q5: 35 | R5: 5 | S5: 41 | T5: =SUM(N5:S5) -> 154 | U5: =T5*60 -> 9240 | V5: 10 | W5: 30 | X5: 45 | Y5: 22 | Z5: 52 | AA5: 5 | AB5: =SUM(V5:AA5) -> 164 | AC5: =AB5*60 -> 9840 | AD5: 37 | AE5: 78 | AF5: 45 | AH5: 12 | AI5: 55 | AJ5: 25 | AK5: =SUM(AD5:AJ5) -> 252 | AL5: =AK5*60 -> 15120 | AS5: VALOR M. | AT5: =AO20 -> 453703
B6: INICIO CARNE | C6: 5 | D6: =SUM(C6:C6) -> 5 | E6: =D6*61 -> 305 | F6: - | G6: 20 | H6: 12 | I6: 46 | J6: 17 | K6: 12 | L6: =SUM(F6:K6) -> 107 | M6: =L6*61 -> 6527 | N6: 8 | O6: 4 | P6: 6 | Q6: 1 | R6: - | S6: 1 | T6: =SUM(N6:S6) -> 20 | U6: =T6*61 -> 1220 | V6: 16 | W6: 7 | X6: 14 | Y6: 9 | Z6: 6 | AA6: - | AB6: =SUM(V6:AA6) -> 52 | AC6: =AB6*61 -> 3172 | AD6: 2 | AE6: 11 | AF6: 15 | AG6: 10 | AH6: 17 | AI6: 15 | AJ6: 8 | AK6: =SUM(AD6:AJ6) -> 78 | AL6: =AK6*61 -> 4758 | AS6: VITAOVO | AT6: =AO48 -> 821
B7: CONEJO | C7: 9 | D7: =SUM(C7:C7) -> 9 | E7: =D7*60 -> 540 | G7: 5 | H7: - | I7: 20 | J7: 20 | K7: 15 | L7: =SUM(F7:K7) -> 60 | M7: =L7*60 -> 3600 | N7: 47 | O7: - | P7: - | Q7: 9 | R7: 5 | S7: 29 | T7: =SUM(N7:S7) -> 90 | U7: =T7*60 -> 5400 | V7: - | W7: 9 | X7: 21 | Y7: 15 | Z7: 25 | AA7: 4 | AB7: =SUM(V7:AA7) -> 74 | AC7: =AB7*60 -> 4440 | AD7: - | AE7: 6 | AF7: - | AH7: 16 | AI7: - | AJ7: 13 | AK7: =SUM(AD7:AJ7) -> 35 | AL7: =AK7*60 -> 2100 | AS7: VALOR M. | AT7: =AO49 -> 79700
B8: CUY | D8: =SUM(C8:C8) -> 0 | E8: =D8*60 -> 0 | F8: 2 | G8: - | H8: - | I8: 25 | J8: 20 | K8: - | L8: =SUM(F8:K8) -> 47 | M8: =L8*60 -> 2820 | N8: 38 | O8: 5 | P8: - | Q8: 15 | R8: - | S8: - | T8: =SUM(N8:S8) -> 58 | U8: =T8*60 -> 3480 | V8: - | W8: 17 | X8: 36 | Y8: - | Z8: 25 | AA8: 2 | AB8: =SUM(V8:AA8) -> 80 | AC8: =AB8*60 -> 4800 | AD8: - | AE8: 29 | AF8: - | AG8: 5 | AH8: 12 | AI8: - | AJ8: 25 | AK8: =SUM(AD8:AJ8) -> 71 | AL8: =AK8*60 -> 4260 | AS8: AFRECHO | AT8: =AO51 -> 517
B9: CON POLLO | C9: 3 | D9: =SUM(C9:C9) -> 3 | E9: =D9*60 -> 180 | F9: 2 | G9: 11 | H9: - | I9: 20 | J9: 10 | K9: 8 | L9: =SUM(F9:K9) -> 51 | M9: =L9*60 -> 3060 | N9: 9 | O9: 6 | P9: 2 | Q9: 1 | R9: - | S9: 5 | T9: =SUM(N9:S9) -> 23 | U9: =T9*60 -> 1380 | V9: - | W9: 4 | X9: - | Y9: 16 | Z9: 20 | AA9: - | AB9: =SUM(V9:AA9) -> 40 | AC9: =AB9*60 -> 2400 | AD9: 54 | AE9: - | AG9: 2 | AH9: - | AI9: - | AJ9: 24 | AK9: =SUM(AD9:AJ9) -> 80 | AL9: =AK9*60 -> 4800 | AS9: VALOR M. | AT9: =AO52 -> 23265
B10: CON CUY | C10: 11 | D10: =SUM(C10:C10) -> 11 | E10: =D10*60 -> 660 | F10: 4 | G10: - | H10: 2 | I10: 15 | J10: 1 | K10: 20 | L10: =SUM(F10:K10) -> 42 | M10: =L10*60 -> 2520 | N10: 6 | O10: 1 | P10: - | R10: - | S10: - | T10: =SUM(N10:S10) -> 7 | U10: =T10*60 -> 420 | V10: - | W10: 5 | X10: - | Y10: 11 | Z10: 7 | AA10: 3 | AB10: =SUM(V10:AA10) -> 26 | AC10: =AB10*60 -> 1560 | AD10: 10 | AE10: 22 | AG10: 5 | AH10: - | AI10: - | AJ10: 12 | AK10: =SUM(AD10:AJ10) -> 49 | AL10: =AK10*60 -> 2940 | AS10: MAIZ | AT10: =AO58 -> 9328
B11: VERDE | C11: 1 | D11: =SUM(C11:C11) -> 1 | E11: =D11*65 -> 65 | F11: - | G11: - | H11: - | I11: 6 | J11: - | K11: 3 | L11: =SUM(F11:K11) -> 9 | M11: =L11*65 -> 585 | N11: 1 | O11: - | P11: 5 | Q11: 2 | R11: - | S11: 3 | T11: =SUM(N11:S11) -> 11 | U11: =T11*65 -> 715 | V11: 3 | W11: 2 | X11: 1 | Y11: 1 | Z11: - | AA11: - | AB11: =SUM(V11:AA11) -> 7 | AC11: =AB11*65 -> 455 | AD11: 1 | AE11: 1 | AF11: 5 | AH11: 6 | AI11: 10 | AJ11: - | AK11: =SUM(AD11:AJ11) -> 23 | AL11: =AK11*65 -> 1495 | AS11: VALOR M. | AT11: =AO59 -> 898799
B12: ROJO | D12: =SUM(C12:C12) -> 0 | E12: =D12*65 -> 0 | F12: 2 | G12: - | H12: - | I12: 6 | J12: 1 | K12: - | L12: =SUM(F12:K12) -> 9 | M12: =L12*65 -> 585 | N12: - | O12: 3 | P12: 15 | Q12: 2 | R12: 5 | S12: 1 | T12: =SUM(N12:S12) -> 26 | U12: =T12*65 -> 1690 | V12: 1 | W12: 2 | X12: 4 | Y12: - | Z12: - | AA12: - | AB12: =SUM(V12:AA12) -> 7 | AC12: =AB12*65 -> 455 | AD12: - | AE12: 1 | AF12: 5 | AH12: 6 | AI12: 10 | AJ12: - | AK12: =SUM(AD12:AJ12) -> 22 | AL12: =AK12*65 -> 1430 | AS12: TRIGO | AT12: =AO61 -> 1278
B13: POLLON | C13: 10 | D13: =SUM(C13:C13) -> 10 | E13: =D13*95 -> 950 | F13: 2 | G13: 48 | H13: 50 | I13: 98 | J13: 20 | K13: 35 | L13: =SUM(F13:K13) -> 253 | M13: =L13*95 -> 24035 | N13: 29 | O13: 2 | P13: 20 | Q13: 32 | R13: 50 | S13: 56 | T13: =SUM(N13:S13) -> 189 | U13: =T13*95 -> 17955 | V13: - | W13: 29 | X13: 34 | Y13: 48 | Z13: 8 | AA13: 20 | AB13: =SUM(V13:AA13) -> 139 | AC13: =AB13*95 -> 13205 | AD13: 15 | AE13: 23 | AF13: 50 | AG13: 74 | AH13: 16 | AI13: - | AJ13: 78 | AK13: =SUM(AD13:AJ13) -> 256 | AL13: =AK13*95 -> 24320 | AS13: VALOR M. | AT13: =AO62 -> 127800
B14: CTO POLLON | C14: 21 | D14: =SUM(C14:C14) -> 21 | E14: =D14*105 -> 2205 | F14: 4 | G14: 23 | H14: 1 | I14: 20 | J14: 30 | K14: - | L14: =SUM(F14:K14) -> 78 | M14: =L14*105 -> 8190 | N14: 58 | O14: 18 | P14: 12 | Q14: 38 | R14: 1 | S14: 6 | T14: =SUM(N14:S14) -> 133 | U14: =T14*105 -> 13965 | V14: 1 | W14: 38 | X14: 47 | Y14: 24 | Z14: - | AA14: 15 | AB14: =SUM(V14:AA14) -> 125 | AC14: =AB14*105 -> 13125 | AD14: 75 | AE14: 34 | AF14: 60 | AG14: 4 | AH14: 18 | AI14: 10 | AJ14: 20 | AK14: =SUM(AD14:AJ14) -> 221 | AL14: =AK14*105 -> 23205
B15: INICIO POLLON | D15: =SUM(C15:C15) -> 0 | E15: =D15*110 -> 0 | F15: - | H15: - | I15: - | J15: 10 | K15: - | L15: =SUM(F15:K15) -> 10 | M15: =L15*110 -> 1100 | N15: 2 | P15: 15 | Q15: 1 | R15: 10 | S15: 5 | T15: =SUM(N15:S15) -> 33 | U15: =T15*110 -> 3630 | W15: 10 | X15: 11 | Y15: 1 | Z15: 2 | AA15: 5 | AB15: =SUM(V15:AA15) -> 29 | AC15: =AB15*110 -> 3190 | AD15: 2 | AE15: 1 | AF15: - | AG15: 20 | AH15: - | AJ15: - | AK15: =SUM(AD15:AJ15) -> 23 | AL15: =AK15*110 -> 2530 | AS15: MAIZ B12 | AT15: 339950
B16: DORIMICYN | D16: =SUM(C16:C16) -> 0 | E16: =D16*70 -> 0 | H16: - | I16: - | K16: 5 | L16: =SUM(F16:K16) -> 5 | M16: =L16*70 -> 350 | N16: 3 | P16: 15 | S16: - | T16: =SUM(N16:S16) -> 18 | U16: =T16*70 -> 1260 | W16: 4 | X16: 20 | Y16: - | AB16: =SUM(V16:AA16) -> 24 | AC16: =AB16*70 -> 1680 | AD16: 10 | AE16: 11 | AH16: - | AJ16: 2 | AK16: =SUM(AD16:AJ16) -> 23 | AL16: =AK16*70 -> 1610
B17: CTO SIMPLE | D17: =SUM(C17:C17) -> 0 | E17: =D17*0 -> 0 | F17: 1 | H17: - | I17: - | L17: =SUM(F17:K17) -> 1 | M17: =L17*0 -> 0 | S17: - | T17: =SUM(N17:S17) -> 0 | U17: =T17*0 -> 0 | Y17: - | AB17: =SUM(V17:AA17) -> 0 | AC17: =AB17*0 -> 0 | AH17: - | AJ17: - | AK17: =SUM(AD17:AJ17) -> 0 | AL17: =AK17*0 -> 0
B18: CTO ANA | D18: =SUM(C18:C18) -> 0 | E18: =D18*0 -> 0 | H18: - | I18: - | L18: =SUM(F18:K18) -> 0 | M18: =L18*0 -> 0 | N18: - | R18: - | S18: - | T18: =SUM(N18:S18) -> 0 | U18: =T18*0 -> 0 | Y18: - | AB18: =SUM(V18:AA18) -> 0 | AC18: =AB18*0 -> 0 | AD18: - | AG18: - | AH18: - | AJ18: - | AK18: =SUM(AD18:AJ18) -> 0 | AL18: =AK18*0 -> 0
D19: =SUM(D4:D16) -> 76 | E19: =SUM(E4:E16) -> 5865 | L19: =SUM(L4:L16) -> 1172 | M19: =SUM(M4:M16) -> 83432 | T19: =SUM(T4:T16) -> 967 | U19: =SUM(U4:U16) -> 72655 | AB19: =SUM(AB4:AB16) -> 932 | AC19: =SUM(AC4:AC16) -> 68222 | AK19: =SUM(AK4:AK16) -> 1406 | AL19: =SUM(AL4:AL16) -> 104948 | AN19: ALIMENTOS | AO19: =D50+L50+T50+AB50+AK50 -> 6162 | AP19: =AO20/AO19 -> 73.629179
B20: CTO BLANCO | D20: =SUM(C20:C20) -> 0 | E20: =D20*85 -> 0 | F20: 4 | G20: - | I20: 10 | J20: 20 | K20: 12 | L20: =SUM(F20:K20) -> 46 | M20: =L20*85 -> 3910 | P20: - | T20: =SUM(N20:S20) -> 0 | U20: =T20*85 -> 0 | W20: 2 | X20: 62 | Y20: - | AB20: =SUM(V20:AA20) -> 64 | AC20: =AB20*85 -> 5440 | AD20: 12 | AH20: 10 | AJ20: 13 | AK20: =SUM(AD20:AJ20) -> 35 | AL20: =AK20*85 -> 2975 | AN20: VALOR M. | AO20: =E50+M50+U50+AC50+AL50 -> 453703
B21: ENG BLANCO | D21: =SUM(C21:C21) -> 0 | E21: =D21*84 -> 0 | F21: 4 | G21: 10 | I21: - | J21: 20 | K21: 4 | L21: =SUM(F21:K21) -> 38 | M21: =L21*84 -> 3192 | N21: 10 | P21: - | T21: =SUM(N21:S21) -> 10 | U21: =T21*84 -> 840 | V21: 5 | X21: 47 | Y21: - | AB21: =SUM(V21:AA21) -> 52 | AC21: =AB21*84 -> 4368 | AD21: 25 | AH21: 10 | AJ21: 7 | AK21: =SUM(AD21:AJ21) -> 42 | AL21: =AK21*84 -> 3528
B22: INICIO BLANCO | D22: =SUM(C22:C22) -> 0 | E22: =D22*85 -> 0 | I22: - | K22: - | L22: =SUM(F22:K22) -> 0 | M22: =L22*85 -> 0 | P22: 80 | Q22: 8 | T22: =SUM(N22:S22) -> 88 | U22: =T22*85 -> 7480 | X22: 17 | Y22: - | AB22: =SUM(V22:AA22) -> 17 | AC22: =AB22*85 -> 1445 | AD22: 10 | AH22: 5 | AJ22: 3 | AK22: =SUM(AD22:AJ22) -> 18 | AL22: =AK22*85 -> 1530
B23: PRE BLANCO | D23: =SUM(C23:C23) -> 0 | E23: =D23*85 -> 0 | I23: - | K23: 4 | L23: =SUM(F23:K23) -> 4 | M23: =L23*85 -> 340 | N23: 4 | P23: 10 | T23: =SUM(N23:S23) -> 14 | U23: =T23*85 -> 1190 | W23: 2 | X23: 10 | Y23: - | AB23: =SUM(V23:AA23) -> 12 | AC23: =AB23*85 -> 1020 | AD23: 13 | AE23: 2 | AK23: =SUM(AD23:AJ23) -> 15 | AL23: =AK23*85 -> 1275
B24: CTO AMARILLO | D24: =SUM(C24:C24) -> 0 | E24: =D24*85 -> 0 | I24: 10 | K24: 10 | L24: =SUM(F24:K24) -> 20 | M24: =L24*85 -> 1700 | P24: 85 | T24: =SUM(N24:S24) -> 85 | U24: =T24*85 -> 7225 | X24: - | Y24: - | AB24: =SUM(V24:AA24) -> 0 | AC24: =AB24*85 -> 0 | AK24: =SUM(AD24:AJ24) -> 0 | AL24: =AK24*85 -> 0 | AN24: LINEA GALLO
B25: ENG AMARILLO | D25: =SUM(C25:C25) -> 0 | E25: =D25*84 -> 0 | I25: 20 | K25: 10 | L25: =SUM(F25:K25) -> 30 | M25: =L25*84 -> 2520 | P25: 165 | T25: =SUM(N25:S25) -> 165 | U25: =T25*84 -> 13860 | X25: - | Y25: 55 | AB25: =SUM(V25:AA25) -> 55 | AC25: =AB25*84 -> 4620 | AK25: =SUM(AD25:AJ25) -> 0 | AL25: =AK25*84 -> 0 | AN25: POLLON | AO25: =D13+L13+T13+AB13+AK13 -> 847
B26: INICIO AMARILLO | D26: =SUM(C26:C26) -> 0 | E26: =D26*85 -> 0 | L26: =SUM(F26:K26) -> 0 | M26: =L26*85 -> 0 | N26: 1 | P26: 5 | T26: =SUM(N26:S26) -> 6 | U26: =T26*85 -> 510 | W26: 2 | X26: - | AB26: =SUM(V26:AA26) -> 2 | AC26: =AB26*85 -> 170 | AE26: 1 | AK26: =SUM(AD26:AJ26) -> 1 | AL26: =AK26*85 -> 85 | AN26: POLLON CTO | AO26: =D14+L14+T14+AB14+AK14 -> 578
B27: PRE AMARILLO | D27: =SUM(C27:C27) -> 0 | E27: =D27*85 -> 0 | L27: =SUM(F27:K27) -> 0 | M27: =L27*85 -> 0 | P27: - | T27: =SUM(N27:S27) -> 0 | U27: =T27*85 -> 0 | X27: - | AB27: =SUM(V27:AA27) -> 0 | AC27: =AB27*85 -> 0 | AK27: =SUM(AD27:AJ27) -> 0 | AL27: =AK27*85 -> 0 | AN27: POLLON INICIO | AO27: =D15+L15+T15+AB15+AK15 -> 95
B28: CUY VITA | D28: =SUM(C28:C28) -> 0 | E28: =D28*75 -> 0 | L28: =SUM(F28:K28) -> 0 | M28: =L28*75 -> 0 | N28: 1 | P28: 35 | Q28: 10 | T28: =SUM(N28:S28) -> 46 | U28: =T28*75 -> 3450 | X28: 5 | Z28: 8 | AB28: =SUM(V28:AA28) -> 13 | AC28: =AB28*75 -> 975 | AK28: =SUM(AD28:AJ28) -> 0 | AL28: =AK28*75 -> 0 | AO28: =SUM(AO25:AO27) -> 1520
B29: CONEJO VITA | D29: =SUM(C29:C29) -> 0 | E29: =D29*75 -> 0 | L29: =SUM(F29:K29) -> 0 | M29: =L29*75 -> 0 | N29: 1 | P29: - | T29: =SUM(N29:S29) -> 1 | U29: =T29*75 -> 75 | X29: - | Z29: 10 | AB29: =SUM(V29:AA29) -> 10 | AC29: =AB29*75 -> 750 | AK29: =SUM(AD29:AJ29) -> 0 | AL29: =AK29*75 -> 0
B30: POSTURA | D30: =SUM(C30:C30) -> 0 | E30: =D30*78 -> 0 | F30: 1 | G30: 5 | H30: 10 | I30: 20 | J30: 20 | K30: 2 | L30: =SUM(F30:K30) -> 58 | M30: =L30*78 -> 4524 | N30: 7 | P30: 85 | S30: 6 | T30: =SUM(N30:S30) -> 98 | U30: =T30*78 -> 7644 | W30: 14 | X30: 10 | Y30: 3 | Z30: 10 | AB30: =SUM(V30:AA30) -> 37 | AC30: =AB30*78 -> 2886 | AD30: 30 | AE30: 6 | AF30: 15 | AK30: =SUM(AD30:AJ30) -> 51 | AL30: =AK30*78 -> 3978
B31: POSTURA ECO. | D31: =SUM(C31:C31) -> 0 | E31: =D31*70 -> 0 | L31: =SUM(F31:K31) -> 0 | M31: =L31*70 -> 0 | T31: =SUM(N31:S31) -> 0 | U31: =T31*70 -> 0 | X31: - | AB31: =SUM(V31:AA31) -> 0 | AC31: =AB31*70 -> 0 | AK31: =SUM(AD31:AJ31) -> 0 | AL31: =AK31*70 -> 0
B32: ROJO PROVINCIA | D32: =SUM(C32:C32) -> 0 | E32: =D32*60 -> 0 | L32: =SUM(F32:K32) -> 0 | M32: =L32*60 -> 0 | T32: =SUM(N32:S32) -> 0 | U32: =T32*60 -> 0 | X32: - | AB32: =SUM(V32:AA32) -> 0 | AC32: =AB32*60 -> 0 | AK32: =SUM(AD32:AJ32) -> 0 | AL32: =AK32*60 -> 0
B33: VERDE PROVINCIA | D33: =SUM(C33:C33) -> 0 | E33: =D33*60 -> 0 | L33: =SUM(F33:K33) -> 0 | M33: =L33*60 -> 0 | T33: =SUM(N33:S33) -> 0 | U33: =T33*60 -> 0 | X33: - | AB33: =SUM(V33:AA33) -> 0 | AC33: =AB33*60 -> 0 | AK33: =SUM(AD33:AJ33) -> 0 | AL33: =AK33*60 -> 0
B34: ENG SIMPLE | D34: =SUM(C34:C34) -> 0 | E34: =D34*40 -> 0 | L34: =SUM(F34:K34) -> 0 | M34: =L34*40 -> 0 | R34: 50 | S34: 10 | T34: =SUM(N34:S34) -> 60 | U34: =T34*40 -> 2400 | X34: - | AB34: =SUM(V34:AA34) -> 0 | AC34: =AB34*40 -> 0 | AK34: =SUM(AD34:AJ34) -> 0 | AL34: =AK34*40 -> 0
B35: CTO SIMPLE | D35: =SUM(C35:C35) -> 0 | E35: =D35*40 -> 0 | I35: 12 | J35: 2 | L35: =SUM(F35:K35) -> 14 | M35: =L35*40 -> 560 | O35: 70 | Q35: 20 | R35: 50 | S35: 32 | T35: =SUM(N35:S35) -> 172 | U35: =T35*40 -> 6880 | X35: - | Y35: 10 | AB35: =SUM(V35:AA35) -> 10 | AC35: =AB35*40 -> 400 | AD35: 28 | AE35: 1 | AF35: 20 | AG35: 15 | AH35: 15 | AK35: =SUM(AD35:AJ35) -> 79 | AL35: =AK35*40 -> 3160
B36: GRANJA X 40 KG | D36: =SUM(C36:C36) -> 0 | E36: =D36*76 -> 0 | L36: =SUM(F36:K36) -> 0 | M36: =L36*76 -> 0 | N36: 10 | T36: =SUM(N36:S36) -> 10 | U36: =T36*76 -> 760 | X36: 61 | AB36: =SUM(V36:AA36) -> 61 | AC36: =AB36*76 -> 4636 | AD36: 30 | AK36: =SUM(AD36:AJ36) -> 30 | AL36: =AK36*76 -> 2280
B37: GRANJA X 50 KG | D37: =SUM(C37:C37) -> 0 | E37: =D37*90 -> 0 | L37: =SUM(F37:K37) -> 0 | M37: =L37*90 -> 0 | T37: =SUM(N37:S37) -> 0 | U37: =T37*90 -> 0 | X37: - | AB37: =SUM(V37:AA37) -> 0 | AC37: =AB37*90 -> 0 | AK37: =SUM(AD37:AJ37) -> 0 | AL37: =AK37*90 -> 0
B38: CTO CON. POLLO | D38: =SUM(C38:C38) -> 0 | E38: =D38*91 -> 0 | L38: =SUM(F38:K38) -> 0 | M38: =L38*91 -> 0 | T38: =SUM(N38:S38) -> 0 | U38: =T38*91 -> 0 | X38: - | AB38: =SUM(V38:AA38) -> 0 | AC38: =AB38*91 -> 0 | AK38: =SUM(AD38:AJ38) -> 0 | AL38: =AK38*91 -> 0
B39: ENG CON. POLLO | D39: =SUM(C39:C39) -> 0 | E39: =D39*90 -> 0 | L39: =SUM(F39:K39) -> 0 | M39: =L39*90 -> 0 | T39: =SUM(N39:S39) -> 0 | U39: =T39*90 -> 0 | X39: - | AB39: =SUM(V39:AA39) -> 0 | AC39: =AB39*90 -> 0 | AK39: =SUM(AD39:AJ39) -> 0 | AL39: =AK39*90 -> 0
B40: CERDO MANTTO | D40: =SUM(C40:C40) -> 0 | E40: =D40*76 -> 0 | L40: =SUM(F40:K40) -> 0 | M40: =L40*76 -> 0 | T40: =SUM(N40:S40) -> 0 | U40: =T40*76 -> 0 | X40: - | AB40: =SUM(V40:AA40) -> 0 | AC40: =AB40*76 -> 0 | AK40: =SUM(AD40:AJ40) -> 0 | AL40: =AK40*76 -> 0
B41: CTO CERDO | D41: =SUM(C41:C41) -> 0 | E41: =D41*100 -> 0 | L41: =SUM(F41:K41) -> 0 | M41: =L41*100 -> 0 | N41: 11 | T41: =SUM(N41:S41) -> 11 | U41: =T41*100 -> 1100 | X41: - | AB41: =SUM(V41:AA41) -> 0 | AC41: =AB41*100 -> 0 | AD41: 17 | AK41: =SUM(AD41:AJ41) -> 17 | AL41: =AK41*100 -> 1700
B42: ENG CERDO | D42: =SUM(C42:C42) -> 0 | E42: =D42*100 -> 0 | L42: =SUM(F42:K42) -> 0 | M42: =L42*100 -> 0 | T42: =SUM(N42:S42) -> 0 | U42: =T42*100 -> 0 | X42: - | AB42: =SUM(V42:AA42) -> 0 | AC42: =AB42*100 -> 0 | AD42: 12 | AK42: =SUM(AD42:AJ42) -> 12 | AL42: =AK42*100 -> 1200
...

Sheet ABRIL
B3: ALIMENTO | C3: 45748 | D3: 45749 | E3: 45750 | F3: 45751 | G3: 45752 | H3: SUB TOTAL | I3: MONTO | J3: 45754 | K3: 45755 | L3: 45756 | M3: 45757 | N3: 45758 | O3: 45759 | P3: SUB TOTAL | Q3: MONTO | R3: 45761 | S3: 45762 | T3: 45763 | U3: 45764 | V3: 45765 | W3: 45766 | X3: SUB TOTAL | Y3: MONTO | Z3: 45768 | AA3: 45769 | AB3: 45770 | AC3: 45771 | AD3: 45772 | AE3: 45773 | AF3: SUB TOTAL | AG3: MONTO | AH3: 45775 | AI3: 45776 | AJ3: 45777 | AK3: SUB TOTAL | AL3: MONTO | AS3: MES : ABRIL
B4: ENG CARNE | C4: 39 | D4: 25 | E4: 82 | F4: 28 | H4: =SUM(C4:G4) -> 174 | I4: =H4*60 -> 10440 | J4: 21 | K4: 97 | M4: 15 | N4: 68 | O4: 26 | P4: =SUM(J4:O4) -> 227 | Q4: =P4*60 -> 13620 | R4: 34 | S4: 51 | T4: 75 | X4: =SUM(R4:W4) -> 160 | Y4: =X4*60 -> 9600 | Z4: 10 | AA4: 22 | AB4: 23 | AC4: 30 | AD4: 62 | AE4: 24 | AF4: =SUM(Z4:AE4) -> 171 | AG4: =AF4*60 -> 10260 | AH4: 50 | AI4: 86 | AJ4: 40 | AK4: =SUM(AH4:AJ4) -> 176 | AL4: =AK4*60 -> 10560 | AS4: ALIMENTOS | AT4: =AO19 -> 6159
B5: CTO CARNE | C5: 23 | D5: 25 | E5: 48 | F5: 42 | G5: 20 | H5: =SUM(C5:G5) -> 158 | I5: =H5*60 -> 9480 | J5: 18 | K5: 77 | M5: 15 | N5: 51 | O5: 30 | P5: =SUM(J5:O5) -> 191 | Q5: =P5*60 -> 11460 | R5: 47 | S5: 71 | T5: 25 | X5: =SUM(R5:W5) -> 143 | Y5: =X5*60 -> 8580 | Z5: 14 | AA5: 3 | AB5: 17 | AC5: 35 | AD5: 66 | AE5: 69 | AF5: =SUM(Z5:AE5) -> 204 | AG5: =AF5*60 -> 12240 | AH5: 70 | AI5: 74 | AJ5: 10 | AK5: =SUM(AH5:AJ5) -> 154 | AL5: =AK5*60 -> 9240 | AS5: VALOR M. | AT5: =AO20 -> 448242
B6: INICIO CARNE | C6: 1 | D6: 1 | E6: 12 | F6: 5 | G6: 5 | H6: =SUM(C6:G6) -> 24 | I6: =H6*61 -> 1464 | J6: 2 | K6: 5 | L6: 6 | M6: - | O6: 5 | P6: =SUM(J6:O6) -> 18 | Q6: =P6*61 -> 1098 | R6: 10 | S6: 15 | T6: 37 | U6: 2 | X6: =SUM(R6:W6) -> 64 | Y6: =X6*61 -> 3904 | Z6: 1 | AA6: 25 | AB6: 10 | AC6: 10 | AD6: 16 | AE6: 40 | AF6: =SUM(Z6:AE6) -> 102 | AG6: =AF6*61 -> 6222 | AH6: 1 | AI6: 9 | AJ6: 15 | AK6: =SUM(AH6:AJ6) -> 25 | AL6: =AK6*61 -> 1525 | AS6: VITAOVO | AT6: =AO48 -> 984
B7: CONEJO | C7: 23 | D7: 16 | E7: 60 | F7: 5 | G7: - | H7: =SUM(C7:G7) -> 104 | I7: =H7*60 -> 6240 | J7: - | K7: 10 | M7: 10 | N7: 25 | O7: 5 | P7: =SUM(J7:O7) -> 50 | Q7: =P7*60 -> 3000 | R7: - | S7: 5 | T7: 32 | X7: =SUM(R7:W7) -> 37 | Y7: =X7*60 -> 2220 | Z7: 20 | AA7: 11 | AB7: 1 | AC7: 10 | AD7: 31 | AE7: - | AF7: =SUM(Z7:AE7) -> 73 | AG7: =AF7*60 -> 4380 | AI7: 10 | AJ7: - | AK7: =SUM(AH7:AJ7) -> 10 | AL7: =AK7*60 -> 600 | AS7: VALOR M. | AT7: =AO49 -> 98126
B8: CUY | C8: 9 | D8: 16 | E8: 40 | F8: - | G8: 5 | H8: =SUM(C8:G8) -> 70 | I8: =H8*60 -> 4200 | J8: 1 | K8: - | N8: 50 | O8: 10 | P8: =SUM(J8:O8) -> 61 | Q8: =P8*60 -> 3660 | R8: 9 | S8: 10 | T8: 10 | X8: =SUM(R8:W8) -> 29 | Y8: =X8*60 -> 1740 | Z8: 12 | AA8: 26 | AB8: 3 | AC8: 10 | AD8: 70 | AE8: 25 | AF8: =SUM(Z8:AE8) -> 146 | AG8: =AF8*60 -> 8760 | AI8: 9 | AJ8: - | AK8: =SUM(AH8:AJ8) -> 9 | AL8: =AK8*60 -> 540 | AS8: AFRECHO | AT8: =AO51 -> 586
B9: CON POLLO | C9: 11 | D9: 6 | E9: - | F9: 13 | G9: 11 | H9: =SUM(C9:G9) -> 41 | I9: =H9*60 -> 2460 | J9: 21 | K9: 10 | M9: 6 | N9: 30 | P9: =SUM(J9:O9) -> 67 | Q9: =P9*60 -> 4020 | R9: 5 | S9: 23 | T9: 11 | X9: =SUM(R9:W9) -> 39 | Y9: =X9*60 -> 2340 | Z9: 2 | AB9: 5 | AC9: 11 | AD9: 16 | AE9: 1 | AF9: =SUM(Z9:AE9) -> 35 | AG9: =AF9*60 -> 2100 | AI9: 22 | AJ9: - | AK9: =SUM(AH9:AJ9) -> 22 | AL9: =AK9*60 -> 1320 | AS9: VALOR M. | AT9: =AO52 -> 27685
B10: CON CUY | C10: 3 | D10: 15 | E10: - | F10: 10 | G10: 10 | H10: =SUM(C10:G10) -> 38 | I10: =H10*60 -> 2280 | J10: 10 | K10: 18 | N10: 22 | O10: 7 | P10: =SUM(J10:O10) -> 57 | Q10: =P10*60 -> 3420 | R10: 1 | S10: 17 | T10: - | X10: =SUM(R10:W10) -> 18 | Y10: =X10*60 -> 1080 | Z10: 1 | AA10: 15 | AB10: 12 | AC10: - | AD10: 16 | AE10: 4 | AF10: =SUM(Z10:AE10) -> 48 | AG10: =AF10*60 -> 2880 | AI10: 19 | AJ10: 5 | AK10: =SUM(AH10:AJ10) -> 24 | AL10: =AK10*60 -> 1440 | AS10: MAIZ | AT10: =AO58 -> 10429
B11: VERDE | C11: 3 | D11: 1 | E11: 10 | F11: 11 | H11: =SUM(C11:G11) -> 25 | I11: =H11*65 -> 1625 | J11: - | K11: 1 | M11: 1 | N11: 1 | P11: =SUM(J11:O11) -> 3 | Q11: =P11*65 -> 195 | R11: 4 | S11: 1 | T11: 12 | X11: =SUM(R11:W11) -> 17 | Y11: =X11*65 -> 1105 | AA11: 8 | AB11: 17 | AC11: 6 | AD11: - | AE11: - | AF11: =SUM(Z11:AE11) -> 31 | AG11: =AF11*65 -> 2015 | AH11: 1 | AI11: 1 | AJ11: 1 | AK11: =SUM(AH11:AJ11) -> 3 | AL11: =AK11*65 -> 195 | AS11: VALOR M. | AT11: =AO59 -> 1029438
B12: ROJO | C12: 1 | D12: - | E12: - | F12: 1 | H12: =SUM(C12:G12) -> 2 | I12: =H12*65 -> 130 | J12: - | K12: - | M12: 1 | N12: 3 | P12: =SUM(J12:O12) -> 4 | Q12: =P12*65 -> 260 | R12: - | S12: 1 | T12: 10 | X12: =SUM(R12:W12) -> 11 | Y12: =X12*65 -> 715 | Z12: 2 | AA12: 5 | AB12: 16 | AC12: 9 | AD12: - | AE12: - | AF12: =SUM(Z12:AE12) -> 32 | AG12: =AF12*65 -> 2080 | AI12: - | AJ12: - | AK12: =SUM(AH12:AJ12) -> 0 | AL12: =AK12*65 -> 0 | AS12: TRIGO | AT12: =AO61 -> 982
B13: POLLON | C13: 2 | D13: 10 | E13: 45 | F13: 23 | G13: 5 | H13: =SUM(C13:G13) -> 85 | I13: =H13*95 -> 8075 | J13: 58 | K13: 47 | N13: 41 | O13: 20 | P13: =SUM(J13:O13) -> 166 | Q13: =P13*95 -> 15770 | R13: 35 | S13: 40 | T13: 18 | U13: 10 | X13: =SUM(R13:W13) -> 103 | Y13: =X13*95 -> 9785 | Z13: 41 | AA13: 15 | AB13: 118 | AC13: 45 | AD13: 81 | AE13: 60 | AF13: =SUM(Z13:AE13) -> 360 | AG13: =AF13*95 -> 34200 | AH13: 7 | AI13: 6 | AJ13: 30 | AK13: =SUM(AH13:AJ13) -> 43 | AL13: =AK13*95 -> 4085 | AS13: VALOR M. | AT13: =AO62 -> 98200
B14: CTO POLLON | C14: 5 | D14: 15 | E14: 20 | F14: 10 | G14: 40 | H14: =SUM(C14:G14) -> 90 | I14: =H14*105 -> 9450 | J14: 61 | K14: 35 | N14: 47 | O14: 18 | P14: =SUM(J14:O14) -> 161 | Q14: =P14*105 -> 16905 | R14: 21 | S14: 34 | T14: 15 | X14: =SUM(R14:W14) -> 70 | Y14: =X14*105 -> 7350 | Z14: 39 | AA14: 16 | AB14: 58 | AC14: 20 | AD14: 50 | AE14: 30 | AF14: =SUM(Z14:AE14) -> 213 | AG14: =AF14*105 -> 22365 | AH14: 1 | AI14: 27 | AJ14: 10 | AK14: =SUM(AH14:AJ14) -> 38 | AL14: =AK14*105 -> 3990
B15: INICIO POLLON | C15: 5 | D15: 4 | E15: 5 | F15: 10 | H15: =SUM(C15:G15) -> 24 | I15: =H15*110 -> 2640 | J15: 10 | K15: 11 | N15: 5 | O15: 5 | P15: =SUM(J15:O15) -> 31 | Q15: =P15*110 -> 3410 | S15: 5 | T15: 1 | X15: =SUM(R15:W15) -> 6 | Y15: =X15*110 -> 660 | Z15: 7 | AB15: 15 | AC15: 2 | AD15: 10 | AE15: - | AF15: =SUM(Z15:AE15) -> 34 | AG15: =AF15*110 -> 3740 | AI15: 1 | AK15: =SUM(AH15:AJ15) -> 1 | AL15: =AK15*110 -> 110 | AS15: MAIZ B12 | AT15: 352650
B16: DORIMICYN | E16: 3 | F16: 5 | H16: =SUM(C16:G16) -> 8 | I16: =H16*70 -> 560 | K16: - | N16: 38 | O16: 3 | P16: =SUM(J16:O16) -> 41 | Q16: =P16*70 -> 2870 | R16: 1 | S16: - | X16: =SUM(R16:W16) -> 1 | Y16: =X16*70 -> 70 | AA16: 24 | AD16: 15 | AE16: 1 | AF16: =SUM(Z16:AE16) -> 40 | AG16: =AF16*70 -> 2800 | AI16: 3 | AK16: =SUM(AH16:AJ16) -> 3 | AL16: =AK16*70 -> 210
B17: CTO SIMPLE | E17: - | H17: =SUM(C17:G17) -> 0 | I17: =H17*0 -> 0 | N17: - | P17: =SUM(J17:O17) -> 0 | Q17: =P17*0 -> 0 | S17: - | X17: =SUM(R17:W17) -> 0 | Y17: =X17*0 -> 0 | AE17: - | AF17: =SUM(Z17:AE17) -> 0 | AG17: =AF17*0 -> 0 | AK17: =SUM(AH17:AJ17) -> 0 | AL17: =AK17*0 -> 0
B18: CTO ANA | E18: - | H18: =SUM(C18:G18) -> 0 | I18: =H18*0 -> 0 | L18: 96 | N18: - | O18: - | P18: =SUM(J18:O18) -> 96 | Q18: =P18*0 -> 0 | S18: - | U18: - | X18: =SUM(R18:W18) -> 0 | Y18: =X18*0 -> 0 | Z18: - | AC18: - | AD18: - | AE18: - | AF18: =SUM(Z18:AE18) -> 0 | AG18: =AF18*0 -> 0 | AH18: - | AI18: - | AK18: =SUM(AH18:AJ18) -> 0 | AL18: =AK18*0 -> 0
H19: =SUM(H4:H16) -> 843 | I19: =SUM(I4:I16) -> 59044 | P19: =SUM(P4:P16) -> 1077 | Q19: =SUM(Q4:Q16) -> 79688 | X19: =SUM(X4:X16) -> 698 | Y19: =SUM(Y4:Y16) -> 49149 | AF19: =SUM(AF4:AF16) -> 1489 | AG19: =SUM(AG4:AG16) -> 114042 | AK19: =SUM(AK4:AK16) -> 508 | AL19: =SUM(AL4:AL16) -> 33815 | AN19: ALIMENTOS | AO19: =H50+P50+X50+AF50+AK50 -> 6159 | AP19: =AO20/AO19 -> 72.778373
B20: CTO BLANCO | E20: 30 | F20: 10 | H20: =SUM(C20:G20) -> 40 | I20: =H20*85 -> 3400 | J20: 5 | K20: 10 | N20: 60 | P20: =SUM(J20:O20) -> 75 | Q20: =P20*85 -> 6375 | R20: 5 | U20: 10 | X20: =SUM(R20:W20) -> 15 | Y20: =X20*85 -> 1275 | AA20: - | AB20: 4 | AD20: 40 | AE20: 40 | AF20: =SUM(Z20:AE20) -> 84 | AG20: =AF20*85 -> 7140 | AH20: 4 | AI20: 3 | AJ20: - | AK20: =SUM(AH20:AJ20) -> 7 | AL20: =AK20*85 -> 595 | AN20: VALOR M. | AO20: =I50+Q50+Y50+AG50+AL50 -> 448242
B21: ENG BLANCO | E21: 31 | F21: 10 | H21: =SUM(C21:G21) -> 41 | I21: =H21*84 -> 3444 | J21: 5 | K21: 10 | N21: 80 | P21: =SUM(J21:O21) -> 95 | Q21: =P21*84 -> 7980 | X21: =SUM(R21:W21) -> 0 | Y21: =X21*84 -> 0 | AA21: 15 | AB21: 5 | AC21: 2 | AD21: 40 | AE21: 70 | AF21: =SUM(Z21:AE21) -> 132 | AG21: =AF21*84 -> 11088 | AH21: 4 | AI21: 1 | AJ21: 10 | AK21: =SUM(AH21:AJ21) -> 15 | AL21: =AK21*84 -> 1260
B22: INICIO BLANCO | F22: - | H22: =SUM(C22:G22) -> 0 | I22: =H22*85 -> 0 | K22: 10 | N22: 6 | P22: =SUM(J22:O22) -> 16 | Q22: =P22*85 -> 1360 | X22: =SUM(R22:W22) -> 0 | Y22: =X22*85 -> 0 | AA22: 10 | AD22: 25 | AE22: 5 | AF22: =SUM(Z22:AE22) -> 40 | AG22: =AF22*85 -> 3400 | AJ22: 6 | AK22: =SUM(AH22:AJ22) -> 6 | AL22: =AK22*85 -> 510
B23: PRE BLANCO | E23: 10 | F23: - | H23: =SUM(C23:G23) -> 10 | I23: =H23*85 -> 850 | N23: 10 | P23: =SUM(J23:O23) -> 10 | Q23: =P23*85 -> 850 | R23: 1 | X23: =SUM(R23:W23) -> 1 | Y23: =X23*85 -> 85 | Z23: 9 | AB23: 3 | AD23: 20 | AE23: 4 | AF23: =SUM(Z23:AE23) -> 36 | AG23: =AF23*85 -> 3060 | AI23: 2 | AK23: =SUM(AH23:AJ23) -> 2 | AL23: =AK23*85 -> 170
B24: CTO AMARILLO | F24: - | H24: =SUM(C24:G24) -> 0 | I24: =H24*85 -> 0 | N24: 20 | P24: =SUM(J24:O24) -> 20 | Q24: =P24*85 -> 1700 | T24: 10 | X24: =SUM(R24:W24) -> 10 | Y24: =X24*85 -> 850 | AA24: 15 | AD24: - | AE24: - | AF24: =SUM(Z24:AE24) -> 15 | AG24: =AF24*85 -> 1275 | AK24: =SUM(AH24:AJ24) -> 0 | AL24: =AK24*85 -> 0 | AN24: LINEA GALLO
B25: ENG AMARILLO | F25: - | H25: =SUM(C25:G25) -> 0 | I25: =H25*84 -> 0 | L25: 9 | N25: 20 | P25: =SUM(J25:O25) -> 29 | Q25: =P25*84 -> 2436 | T25: 30 | X25: =SUM(R25:W25) -> 30 | Y25: =X25*84 -> 2520 | Z25: 5 | AA25: 25 | AD25: - | AF25: =SUM(Z25:AE25) -> 30 | AG25: =AF25*84 -> 2520 | AK25: =SUM(AH25:AJ25) -> 0 | AL25: =AK25*84 -> 0 | AN25: POLLON | AO25: =H13+P13+X13+AF13+AK13 -> 757
B26: INICIO AMARILLO | C26: 1 | F26: - | H26: =SUM(C26:G26) -> 1 | I26: =H26*85 -> 85 | N26: 10 | P26: =SUM(J26:O26) -> 10 | Q26: =P26*85 -> 850 | X26: =SUM(R26:W26) -> 0 | Y26: =X26*85 -> 0 | Z26: 1 | AA26: 20 | AD26: - | AF26: =SUM(Z26:AE26) -> 21 | AG26: =AF26*85 -> 1785 | AI26: 2 | AK26: =SUM(AH26:AJ26) -> 2 | AL26: =AK26*85 -> 170 | AN26: POLLON CTO | AO26: =H14+P14+X14+AF14+AK14 -> 572
B27: PRE AMARILLO | F27: - | H27: =SUM(C27:G27) -> 0 | I27: =H27*85 -> 0 | N27: - | P27: =SUM(J27:O27) -> 0 | Q27: =P27*85 -> 0 | X27: =SUM(R27:W27) -> 0 | Y27: =X27*85 -> 0 | AD27: - | AF27: =SUM(Z27:AE27) -> 0 | AG27: =AF27*85 -> 0 | AK27: =SUM(AH27:AJ27) -> 0 | AL27: =AK27*85 -> 0 | AN27: POLLON INICIO | AO27: =H15+P15+X15+AF15+AK15 -> 96
B28: CUY VITA | F28: - | H28: =SUM(C28:G28) -> 0 | I28: =H28*75 -> 0 | J28: 15 | N28: - | P28: =SUM(J28:O28) -> 15 | Q28: =P28*75 -> 1125 | U28: 10 | X28: =SUM(R28:W28) -> 10 | Y28: =X28*75 -> 750 | AA28: 7 | AB28: 2 | AD28: 20 | AF28: =SUM(Z28:AE28) -> 29 | AG28: =AF28*75 -> 2175 | AI28: 1 | AK28: =SUM(AH28:AJ28) -> 1 | AL28: =AK28*75 -> 75 | AO28: =SUM(AO25:AO27) -> 1425
B29: CONEJO VITA | F29: - | H29: =SUM(C29:G29) -> 0 | I29: =H29*75 -> 0 | N29: - | P29: =SUM(J29:O29) -> 0 | Q29: =P29*75 -> 0 | U29: 13 | X29: =SUM(R29:W29) -> 13 | Y29: =X29*75 -> 975 | AD29: 15 | AF29: =SUM(Z29:AE29) -> 15 | AG29: =AF29*75 -> 1125 | AK29: =SUM(AH29:AJ29) -> 0 | AL29: =AK29*75 -> 0
B30: POSTURA | C30: 2 | F30: 9 | H30: =SUM(C30:G30) -> 11 | I30: =H30*78 -> 858 | J30: 6 | N30: 50 | O30: 8 | P30: =SUM(J30:O30) -> 64 | Q30: =P30*78 -> 4992 | R30: 13 | S30: 15 | T30: 30 | X30: =SUM(R30:W30) -> 58 | Y30: =X30*78 -> 4524 | Z30: 2 | AA30: 30 | AB30: 1 | AD30: 27 | AE30: 20 | AF30: =SUM(Z30:AE30) -> 80 | AG30: =AF30*78 -> 6240 | AI30: 6 | AJ30: 10 | AK30: =SUM(AH30:AJ30) -> 16 | AL30: =AK30*78 -> 1248
